Workbook

Sheet 이마트_260819
A1: 26/08/19(수) 옥천농협 배송 | C1: 유기농 가바현미 | D1: 유기농 가바백미 | E1: 유기농 가바백미 | F1: 유기농 천지향 | G1: 유기농 귀리쌀 | H1: 유기농 천지향5세 오분도미
A2: 포장지 | C2: PET | D2: 자연주의 | E2: 자연주의 | F2: 자연주의 | G2: PET | H2: 자연주의
A3: 중량 | C3: 1kg | D3: 4kg | E3: 1 kg | F3: 4kg | G3: 420g | H3: 4kg
A4: 소계 | C4: =SUM(C6:C8) -> 10 | D4: =SUM(D6:D8) -> 0 | E4: =SUM(E6:E8) -> 240 | F4: =SUM(F6:F8) -> 64 | G4: =SUM(G6:G8) -> 60 | H4: =SUM(H6:H8) -> 0
A5: (발주처) | B5: (수령인)
A6: 이마트 | B6: 여주지점 | E6: 112 | F6: 24 | G6: 20
A7: 이마트 | B7: 대구지점 | E7: 32 | F7: 24
A8: 이마트 | B8: 시화지점 | C8: 10 | E8: 96 | F8: 16 | G8: 40
C11: 현미1kg | D11: 가바4kg | E11: 가바1kg | F11: 천지향4kg | G11: 귀리420g | H11: 5분도미4kg
A12: 여주(이마트) | E12: =E6/16 -> 7 | F12: =F6/4 -> 6 | G12: =G6/20 -> 1 | I12: =SUM(C12:H12) -> 14 | J12: 1파렛
A13: 대구(이마트) | E13: =E7/16 -> 2 | F13: =F7/4 -> 6 | I13: =SUM(C13:H13) -> 8
A14: 시화(이마트) | C14: =C8/10 -> 1 | E14: =E8/16 -> 6 | F14: =F8/4 -> 4 | G14: =G8/20 -> 2 | I14: =SUM(C14:H14) -> 13 | J14: 1파렛

Sheet 택배_260818
A1: 26/08/18 (화) | C1: 유기농 찹쌀 | D1: 유기농 천지향 | H1: 유기농 하이아미 | M1: 유기농 가바백미 | P1: 유기농 가바흑미 | Q1: 유기농 가바 발아현미 | R1: 유기농 가바현미 | S1: 유기농 찰보리 | T1: 유기농 귀리 | U1: 유기농 검정보리 | V1: 유기농 차조 | W1: 유기농 수수 | X1: 유기농 기장 | Y1: 유기농 프로틴 라이스 IPS | Z1: 유기농 IPS | AA1: 누룽지
A2: 포장지 | E2: 자연 주의 | H2: 아이담쌀 | O2: 자연 주의
A3: 중량 | C3: 5kg | D3: 1kg | E3: 4kg | F3: 5kg | G3: 10kg | H3: 3kg | I3: 5kg | J3: 4kg | K3: 5kg | L3: 10kg | M3: 1kg | N3: 3kg | O3: 4kg | P3: 800g | Q3: 800g | R3: 800g | S3: 1kg | T3: 1kg | U3: 1kg | V3: 1kg | W3: 1kg | X3: 1kg | Y3: 907g | Z3: 10kg | AA3: 1kg
A4: 소계 | C4: =SUM(C6:C74) -> 1 | D4: =SUM(D6:D74) -> 40 | E4: =SUM(E6:E74) -> 18 | F4: =SUM(F6:F74) -> 32 | G4: =SUM(G6:G74) -> 13 | H4: =SUM(H6:H74) -> 18 | I4: =SUM(I6:I74) -> 16 | J4: =SUM(J6:J74) -> 3 | ... AA4: =SUM(AA6:AA74) -> 20
A5: (발주처) | B5: (수령인)
A6: 땅끝황토친환경 | B6: 이마트연수점 | E6: 6
A7: 땅끝황토친환경 | B7: 이마트풍산점 | E7: 4
A8: 땅끝황토친환경 | B8: 이마트명일점 | E8: 3
A9: 땅끝황토친환경 | B9: 이마트신월점 | E9: 1
A10: 땅끝황토친환경 | B10: 이마트일산점 | E10: 1
A11: 땅끝황토친환경 | B11: 이마트수성점 | E11: 1
A12: 땅끝황토친환경 | B12: 이마트동인천점 | E12: 1
A13: 땅끝황토친환경 | B13: 이마트광산점 | E13: 1
A14: 땅끝황토친환경 | B14: 이마트본사 김보훈 | O14: 8
A15: 쿠팡wing | B15: 이선우 | L15: 1
A16: 쿠팡wing | B16: LIUYUSHAN | G16: 1
A17: 쿠팡wing | B17: 나혜경 | G17: 1
A18: 쿠팡wing | B18: 성수옥 | AA18: 2
A19: 쿠팡wing | B19: 김지희 | L19: 1
A20: 우리아이행복밥상 | B20: 울림생협 성산점 | F20: 8
A21: 우리아이행복밥상 | B21: 울림생협 북가좌점 | F21: 4
A22: 서대문마을생협 | B22: 꼬마박사어린이집 | G22: 1
A23: 서대문마을생협 | B23: 별빛어린이집 | G23: 1
A24: 서대문마을생협 | B24: 신촌어린이집 | G24: 2
A25: 서대문마을생협 | B25: 서대문마을생협 | D25: 40 | F25: 8 | G25: 4
A26: 일반판매 | B26: 서보람 | Z26: 1
A27: 해남미소 | B27: 임수진 | S27: 1
A28: 해남미소 | B28: 김선희 | S28: 4
A29: 해남미소 | B29: 신득희 | T29: 2
A30: 해남미소 | B30: 정승준 | T30: 2
A31: 해남미소 | B31: 박혜원 | L31: 1
A32: 해남미소 | B32: 한경철 | T32: 2
A33: 해남미소 | B33: 정우식 | W33: 2
A34: 네이버스토어 | B34: 김성욱 | L34: 1
A35: 네이버스토어 | B35: 최지애 | Q35: 1 | V35: 1
A36: 네이버스토어 | B36: 유종훈 | G36: 1
A37: 네이버스토어 | B37: 윤서우 | L37: 1
A38: 네이버스토어 | B38: 진 이 | M38: 4 | Y38: 1
A39: 네이버스토어 | B39: 임효진 | K39: 1
A40: 네이버스토어 | B40: 윤세라 | P40: 1 | R40: 1
...

Sheet 서울급식_060818
A1: 26/08/18 (화) 서울급식 | C1: 유기농 새청무 | F1: 유기농 현미 | I1: 유기농 찹쌀 | L1: 유기농 찹쌀현미 | O1: 유기농 귀리 | P1: 유기농 보리 | Q1: 유기농 기장 | R1: 유기농 흑미 | T1: 유기농 차조 | U1: 유기농 발아현미 | V1: 유기농 수수 | W1: 유기농 쥐눈이콩 | Y1: 유기농 팥 | AA1: 칼슘기장 (일반) | AB1: 혼합곡 (친환경) | AC1: 율무 (친환경) | AD1: 녹두 (친환경)
A2: 포장지
A3: 중량 | C3: 1 | D3: 5 | E3: 10 | F3: 1 | G3: 5 | H3: 10 | I3: 1 | J3: 5 | K3: 10 | L3: 1 | M3: 5 | N3: 10 | O3: 1 | P3: 1 | Q3: 1 | R3: 500 | S3: 1 | T3: 1 | U3: 1 | V3: 1 | W3: 500 | X3: 1 | Y3: 500 | Z3: 1 | AA3: 1 | AB3: 1 | AC3: 1 | AD3: 1
A4: 소계 | C4: =SUM(C5:C8) -> 33 | D4: =SUM(D5:D8) -> 13 | E4: =SUM(E5:E8) -> 168 | F4: =SUM(F5:F8) -> 0 | G4: =SUM(G5:G8) -> 0 | H4: =SUM(H5:H8) -> 0 | I4: =SUM(I5:I8) -> 37 | J4: =SUM(J5:J8) -> 6 | ... AD4: =SUM(AD5:AD8) -> 1
A5: (발주처) | B5: (수령인)
A6: 은평구 | B6: 행복플러스 | C6: =SUMIFS('[1]은평구08.18'!$G:$G, '[1]은평구08.18'!$D:$D, "백미(친환경)") -> 31 | D6: =SUMIFS('[1]은평구08.18'!$F:$F, '[1]은평구08.18'!$D:$D, "백미(친환경)") -> 6 | E6: =SUMIFS('[1]은평구08.18'!$E:$E, '[1]은평구08.18'!$D:$D, "백미(친환경)") -> 91 | F6: =SUMIFS('[1]은평구08.18'!$G:$G, '[1]은평구08.18'!$D:$D, "현미(친환경)") -> 0 | G6: =SUMIFS('[1]은평구08.18'!$F:$F, '[1]은평구08.18'!$D:$D, "현미(친환경)") -> 0 | H6: =SUMIFS('[1]은평구08.18'!$E:$E, '[1]은평구08.18'!$D:$D, "현미(친환경)") -> 0 | I6: =SUMIFS('[1]은평구08.18'!$G:$G, '[1]은평구08.18'!$D:$D, "찹쌀(친환경)") -> 37 | J6: =SUMIFS('[1]은평구08.18'!$F:$F, '[1]은평구08.18'!$D:$D, "찹쌀(친환경)") -> 6 | K6: =SUMIFS('[1]은평구08.18'!$E:$E, '[1]은평구08.18'!$D:$D, "찹쌀(친환경)") -> 0 | L6: =SUMIFS('[1]은평구08.18'!$G:$G, '[1]은평구08.18'!$D:$D, "찹쌀현미(친환경)") -> 2 | M6: =SUMIFS('[1]은평구08.18'!$F:$F, '[1]은평구08.18'!$D:$D, "찹쌀현미(친환경)") -> 0 | N6: =SUMIFS('[1]은평구08.18'!$E:$E, '[1]은평구08.18'!$D:$D, "찹쌀현미(친환경)") -> 0 | O6: =SUMIFS('[1]은평구08.18'!$G:$G, '[1]은평구08.18'!$D:$D, "귀리(친환경)") -> 2 | P6: =SUMIFS('[1]은평구08.18'!$G:$G, '[1]은평구08.18'!$D:$D, "보리(친환경)") -> 0 | Q6: =SUMIFS('[1]은평구08.18'!$G:$G, '[1]은평구08.18'!$D:$D, "기장(친환경)") -> 9 | R6: =SUMIFS('[1]은평구08.18'!$H:$H, '[1]은평구08.18'!$D:$D, "흑미(친환경)") -> 1 | S6: =SUMIFS('[1]은평구08.18'!$G:$G, '[1]은평구08.18'!$D:$D, "흑미(친환경)") -> 2 | T6: =SUMIFS('[1]은평구08.18'!$G:$G, '[1]은평구08.18'!$D:$D, "차조(친환경)") -> 2 | U6: =SUMIFS('[1]은평구08.18'!$G:$G, '[1]은평구08.18'!$D:$D, "발아현미(친환경)") -> 9 | V6: =SUMIFS('[1]은평구08.18'!$G:$G, '[1]은평구08.18'!$D:$D, "수수(친환경)") -> 2 | W6: =SUMIFS('[1]은평구08.18'!$H:$H, '[1]은평구08.18'!$D:$D, "쥐눈이콩(친환경)") -> 0 | X6: =SUMIFS('[1]은평구08.18'!$G:$G, '[1]은평구08.18'!$D:$D, "쥐눈이콩(친환경)") -> 0 | Y6: =SUMIFS('[1]은평구08.18'!$H:$H, '[1]은평구08.18'!$D:$D, "팥(친환경)") -> 0 | Z6: =SUMIFS('[1]은평구08.18'!$G:$G, '[1]은평구08.18'!$D:$D, "팥(친환경)") -> 0 | AA6: =SUMIFS('[1]은평구08.18'!$G:$G, '[1]은평구08.18'!$D:$D, "칼슘기장(일반)") -> 0 | AB6: =SUMIFS('[1]은평구08.18'!$G:$G, '[1]은평구08.18'!$D:$D, "혼합곡(친환경)") -> 4 | AC6: =SUMIFS('[1]은평구08.18'!$G:$G, '[1]은평구08.18'!$D:$D, "율무(친환경)") -> 2 | AD6: =SUMIFS('[1]은평구08.18'!$G:$G, '[1]은평구08.18'!$D:$D, "녹두(친환경)") -> 1
A7: 서대문구 | B7: 행복플러스 | C7: =SUMIFS([1]서대문구08.18!$G:$G, [1]서대문구08.18!$D:$D, "백미(친환경)") -> 2 | D7: =SUMIFS([1]서대문구08.18!$F:$F, [1]서대문구08.18!$D:$D, "백미(친환경)") -> 7 | E7: =SUMIFS([1]서대문구08.18!$E:$E, [1]서대문구08.18!$D:$D, "백미(친환경)") -> 75 | F7: =SUMIFS([1]서대문구08.18!$G:$G, [1]서대문구08.18!$D:$D, "현미(친환경)") -> 0 | G7: =SUMIFS([1]서대문구08.18!$F:$F, [1]서대문구08.18!$D:$D, "현미(친환경)") -> 0 | H7: =SUMIFS([1]서대문구08.18!$E:$E, [1]서대문구08.18!$D:$D, "현미(친환경)") -> 0 | I7: =SUMIFS([1]서대문구08.18!$G:$G, [1]서대문구08.18!$D:$D, "찹쌀(친환경)") -> 0 | J7: =SUMIFS([1]서대문구08.18!$F:$F, [1]서대문구08.18!$D:$D, "찹쌀(친환경)") -> 0 | K7: =SUMIFS([1]서대문구08.18!$E:$E, [1]서대문구08.18!$D:$D, "찹쌀(친환경)") -> 6 | L7: =SUMIFS([1]서대문구08.18!$G:$G, [1]서대문구08.18!$D:$D, "찹쌀현미(친환경)") -> 0 | M7: =SUMIFS([1]서대문구08.18!$F:$F, [1]서대문구08.18!$D:$D, "찹쌀현미(친환경)") -> 0 | N7: =SUMIFS([1]서대문구08.18!$E:$E, [1]서대문구08.18!$D:$D, "찹쌀현미(친환경)") -> 0 | O7: =SUMIFS([1]서대문구08.18!$G:$G, [1]서대문구08.18!$D:$D, "귀리(친환경)") -> 0 | P7: =SUMIFS([1]서대문구08.18!$G:$G, [1]서대문구08.18!$D:$D, "보리(친환경)") -> 0 | Q7: =SUMIFS([1]서대문구08.18!$G:$G, [1]서대문구08.18!$D:$D, "기장(친환경)") -> 3 | R7: =SUMIFS([1]서대문구08.18!$H:$H, [1]서대문구08.18!$D:$D, "흑미(친환경)") -> 0 | S7: =SUMIFS([1]서대문구08.18!$G:$G, [1]서대문구08.18!$D:$D, "흑미(친환경)") -> 3 | T7: =SUMIFS([1]서대문구08.18!$G:$G, [1]서대문구08.18!$D:$D, "차조(친환경)") -> 0 | U7: =SUMIFS([1]서대문구08.18!$G:$G, [1]서대문구08.18!$D:$D, "발아현미(친환경)") -> 3 | V7: =SUMIFS([1]서대문구08.18!$G:$G, [1]서대문구08.18!$D:$D, "수수(친환경)") -> 0 | W7: =SUMIFS([1]서대문구08.18!$H:$H, [1]서대문구08.18!$D:$D, "쥐눈이콩(친환경)") -> 0 | X7: =SUMIFS([1]서대문구08.18!$G:$G, [1]서대문구08.18!$D:$D, "쥐눈이콩(친환경)") -> 0 | Y7: =SUMIFS([1]서대문구08.18!$H:$H, [1]서대문구08.18!$D:$D, "팥(친환경)") -> 0 | Z7: =SUMIFS([1]서대문구08.18!$G:$G, [1]서대문구08.18!$D:$D, "팥(친환경)") -> 0 | AA7: =SUMIFS([1]서대문구08.18!$G:$G, [1]서대문구08.18!$D:$D, "칼슘기장(일반)") -> 0 | AB7: =SUMIFS([1]서대문구08.18!$G:$G, [1]서대문구08.18!$D:$D, "혼합곡(친환경)") -> 0 | AC7: =SUMIFS([1]서대문구08.18!$G:$G, [1]서대문구08.18!$D:$D, "율무(친환경)") -> 0 | AD7: =SUMIFS([1]서대문구08.18!$G:$G, [1]서대문구08.18!$D:$D, "녹두(친환경)") -> 0
A8: 여유 | B8: 행복플러스 | E8: 2

Sheet 해남급식_260821
A1: 26/08/21 (금) 해남군공공급식 | C1: 유기농 백미 천지향5세 | E1: 유기농 찹쌀 | G1: 유기농 찹쌀현미 | H1: 유기농 현미 | I1: 유기농 귀리 | J1: 유기농 보리 | K1: 유기농 기장 | L1: 유기농 흑미 | M1: 유기농 차조 | N1: 유기농 발아현미 | O1: 유기농 수수 | P1: 유기농 쥐눈이콩 | Q1: 유기농 팥 | R1: 유기농 서리태
A2: 포장지
A3: 중량 | C3: 10kg | D3: 1kg | E3: 10kg | F3: 1kg | G3: 1kg | H3: 1kg | I3: 1kg | J3: 1kg | K3: 1kg | L3: 1kg | M3: 1kg | N3: 1kg | O3: 1kg | P3: 1kg | Q3: 1kg | R3: 1kg
A4: 소계 | C4: =SUM(C5:C11) -> 74 | D4: =SUM(D5:D11) -> 0 | E4: =SUM(E5:E11) -> 8 | F4: =SUM(F5:F11) -> 35 | G4: =SUM(G5:G11) -> 0 | H4: =SUM(H5:H11) -> 0 | I4: =SUM(I5:I11) -> 3 | J4: =SUM(J5:J11) -> 9 | ... R4: =SUM(R5:R11) -> 0
A5: (발주처) | B5: (수령인)
A6: 해남급식 | B6: 싱싱유통 | C6: ='[2]학교별08.21'!C22 -> 66 | D6: ='[2]학교별08.21'!D22 -> 0 | E6: ='[2]학교별08.21'!E22 -> 5 | F6: ='[2]학교별08.21'!F22 -> 35
A7: 해남급식 | B7: 급식센터 | C7: ='[2]학교별08.21'!C43 -> 8 | D7: ='[2]학교별08.21'!D43 -> 0 | E7: ='[2]학교별08.21'!E43 -> 3 | F7: ='[2]학교별08.21'!F43 -> 0 | G7: ='[2]학교별08.21'!H3 -> 0 | H7: ='[2]학교별08.21'!I3 -> 0 | I7: ='[2]학교별08.21'!J3 -> 3 | J7: ='[2]학교별08.21'!K3 -> 9 | K7: ='[2]학교별08.21'!L3 -> 3 | L7: ='[2]학교별08.21'!M3 -> 0 | M7: ='[2]학교별08.21'!N3 -> 3 | N7: ='[2]학교별08.21'!O3 -> 0 | ... R7: ='[2]학교별08.21'!S3 -> 0
A8: 해남급식 | B8: 땅끝농협 | C8: ='[2]학교별08.21'!C52 -> 0 | D8: ='[2]학교별08.21'!D52 -> 0 | E8: ='[2]학교별08.21'!E52 -> 0 | F8: ='[2]학교별08.21'!F52 -> 0
A9: 해남급식 | B9: 참솔 | C9: ='[2]학교별08.21'!C62 -> 0 | D9: ='[2]학교별08.21'!D62 -> 0 | E9: ='[2]학교별08.21'!E62 -> 0 | F9: ='[2]학교별08.21'!F62 -> 0

Sheet 시아스_260811
A1: 8/11(화) 오후상차 | B1: 유기농 가바백미 | D1: 유기농 가바현미
A2: 포장지 | B2: 톤백 | C2: 톤백 | D2: 톤백 | E2: 톤백
A3: 중량 | B3: 1,000kg | C3: 200kg | D3: 1,000kg | E3: 200kg
A4: 소계 | B4: =SUM(B5:B5) -> 1 | C4: =SUM(C5:C5) -> 1 | D4: =SUM(D5:D5) -> 1 | E4: =SUM(E5:E5) -> 1
A5: 시아스 | B5: 1 | C5: 1 | D5: 1 | E5: 1
