Workbook

Sheet 학교별01.02
A1: 1/2(금) 해남군공공급식 (1/5~1/8 발주량) | C1: 유기농 백미 ( ) | E1: 유기농 찹쌀 ( ) | H1: 유기농 찹쌀현미 ( ) | I1: 유기농 현미 ( ) | J1: 유기농 귀리 ( ) | K1: 유기농 보리 ( ) | L1: 유기농 기장 ( ) | M1: 유기농 흑미 ( ) | N1: 유기농 차조 ( ) | O1: 유기농 서리태 ( ) | P1: 유기농 발아현미 ( ) | Q1: 유기농 쥐눈이콩 ( ) | R1: 유기농 수수 ( ) | S1: 소면 ( ) | T1: 중면 ( ) | U1: 칼국수 ( )
C2: 10kg | D2: 1kg | E2: 10kg | F2: 1kg | H2: 1kg | I2: 1kg | J2: 1kg | K2: 1kg | L2: 1kg | M2: 1kg | N2: 1kg | O2: 1kg | P2: 1kg | Q2: 1kg | R2: 1kg | S2: 1kg | T2: 1kg | U2: 1kg
A3: 업체 | B3: 품목별 소계 | C3: =C31+C58+C67 -> 22 | D3: =D31+D58+D67 -> 0 | E3: =E31+E58+E67 -> 0 | F3: =F31+F58+F67 -> 0 | H3: =H31+H58+H67 -> 0 | I3: =I31+I58+I67 -> 0 | J3: =J31+J58+J67 -> 2 | K3: =K31+K58+K67 -> 1 | L3: =L31+L58+L67 -> 0 | M3: =M31+M58+M67 -> 0 | N3: =N31+N58+N67 -> 0 | O3: =O31+O58+O67 -> 0 | ... U3: =U31+U58+U67 -> 0 | V3: =D3*10 -> 0 | W3: =F3*10+E3 -> 0 | X3: =SUM(H3:Q3) -> 3 | Y3: =SUM(V3:X3) -> 3
A4: 싱싱 유통 | B4: 계곡중학교
B5: 계곡초등학교
B6: 두륜중학교
B7: 마산초등학교
B8: 북일초등학교
B9: 북평중학교
B10: 북평초등학교
B11: 산이서초등학교
B12: 산이중학교
B13: 산이초등학교
B14: 삼산초등학교
B15: 옥천초등학교
B16: 우수영중학교
... B18: 해남고등학교
B19: 해남동초등학교 | J19: 2 | R19: 2
B20: 해오름유치원
B21: 현산남초등학교
B22: 현산중학교
B23: 현산초등학교
B24: 화산중학교
B25: 화산초등학교
B26: 화원고등학교
B27: 화원중학교
B28: 화원초등학교 | K28: 1
B29: 황산중학교
B30: 황산초등학교
C31: =SUM(C4:C30) -> 0 | D31: =SUM(D4:D30) -> 0 | E31: =SUM(E4:E30) -> 0 | F31: =SUM(F4:F30) -> 0 | H31: =SUM(H4:H30) -> 0 | I31: =SUM(I4:I30) -> 0 | J31: =SUM(J4:J30) -> 2 | K31: =SUM(K4:K30) -> 1 | L31: =SUM(L4:L30) -> 0 | M31: =SUM(M4:M30) -> 0 | N31: =SUM(N4:N30) -> 0 | O31: =SUM(O4:O30) -> 0 | ... U31: =SUM(U4:U30) -> 0
A32: 공공 급식 센터 | B32: 공립시등어린이집
B33: 공립한듬어린이집 | C33: 3
B34: 공립해남어린이집
B35: 공립해담어린이집
B36: 공립화원어린이집
B37: 동심어린이집
B38: 둘리어린이집
B39: 리틀어린이집
B40: 미래클유치원
B41: 벧엘특수어린이집 | C41: 2
...

Sheet 공장동01.02
A1: 1/2(금) 해남군공공급식 (1/5~1/8 발주량) | C1: 유기농 백미 천지향 ( ) | E1: 유기농 찹쌀 ( ) | H1: 급식센터 입고 | I1: 유기농 찹쌀현미 ( ) | J1: 유기농 현미 ( ) | K1: 유기농 귀리 (박태일) | L1: 유기농 보리 (김종원) | M1: 유기농 기장 (박태일) | N1: 유기농 흑미 (박태일) | O1: 유기농 차조 (신승철) | P1: 유기농 서리태 (이관) | Q1: 유기농 발아현미 (곽해용) | R1: 유기농 쥐눈이콩 (신승철) | S1: 유기농 수수 (윤영식) | T1: 소면 ( ) | U1: 중면 ( ) | V1: 칼국수면 ( )
C2: 10kg | D2: 1kg | E2: 10kg | F2: 1kg | I2: 1kg | J2: 1kg | K2: 1kg | L2: 1kg | M2: 1kg | N2: 1kg | O2: 1kg | P2: 1kg | Q2: 1kg | R2: 1kg | S2: 1kg | T2: 1kg | U2: 1kg | V2: 1kg
A3: 품목별 소계 | C3: =SUM(C4:C19) -> 22 | D3: =SUM(D4:D19) -> 0 | E3: =SUM(E4:E19) -> 0 | F3: =SUM(F4:F19) -> 0 | H3: 품목별 소계 | I3: =SUM(I4:I11) -> 0 | J3: =SUM(J4:J11) -> 0 | K3: =SUM(K4:K11) -> 2 | L3: =SUM(L4:L11) -> 1 | M3: =SUM(M4:M11) -> 0 | N3: =SUM(N4:N11) -> 0 | O3: =SUM(O4:O11) -> 0 | P3: =SUM(P4:P11) -> 0 | ... V3: =SUM(V4:V11) -> 0
A4: 싱싱유통 | C4: ='학교별01.02'!C31 -> 0 | D4: ='학교별01.02'!D31 -> 0 | E4: ='학교별01.02'!E31 -> 0 | F4: ='학교별01.02'!F31 -> 0 | H4: 싱싱유통 | I4: ='학교별01.02'!H31 -> 0 | J4: ='학교별01.02'!I31 -> 0 | K4: ='학교별01.02'!J31 -> 2 | L4: ='학교별01.02'!K31 -> 1 | M4: ='학교별01.02'!L31 -> 0 | N4: ='학교별01.02'!M31 -> 0 | O4: ='학교별01.02'!N31 -> 0 | P4: ='학교별01.02'!O31 -> 0 | ... V4: ='학교별01.02'!U31 -> 0
A7: 공공급식센터 | C7: ='학교별01.02'!C58 -> 22 | D7: ='학교별01.02'!D58 -> 0 | E7: ='학교별01.02'!E58 -> 0 | F7: ='학교별01.02'!F58 -> 0 | H7: 급식센터 | I7: ='학교별01.02'!H58 -> 0 | J7: ='학교별01.02'!I58 -> 0 | K7: ='학교별01.02'!J58 -> 0 | L7: ='학교별01.02'!K58 -> 0 | M7: ='학교별01.02'!L58 -> 0 | N7: ='학교별01.02'!M58 -> 0 | O7: ='학교별01.02'!N58 -> 0 | P7: ='학교별01.02'!O58 -> 0 | ... V7: ='학교별01.02'!U58 -> 0
A10: 땅끝농협 | C10: ='학교별01.02'!C67 -> 0 | D10: ='학교별01.02'!D67 -> 0 | E10: ='학교별01.02'!E67 -> 0 | F10: ='학교별01.02'!F67 -> 0 | H10: 땅끝농협 | I10: ='학교별01.02'!H67 -> 0 | J10: ='학교별01.02'!I67 -> 0 | K10: ='학교별01.02'!J67 -> 0 | L10: ='학교별01.02'!K67 -> 0 | M10: ='학교별01.02'!L67 -> 0 | N10: ='학교별01.02'!M67 -> 0 | O10: ='학교별01.02'!N67 -> 0 | P10: ='학교별01.02'!O67 -> 0 | ... V10: ='학교별01.02'!U67 -> 0

Sheet 학교별01.09
A1: 1/9(금) 해남군공공급식 (1/12~1/16 발주량) | C1: 유기농 백미 ( ) | E1: 유기농 찹쌀 ( ) | H1: 유기농 찹쌀현미 ( ) | I1: 유기농 현미 ( ) | J1: 유기농 귀리 ( ) | K1: 유기농 보리 ( ) | L1: 유기농 기장 ( ) | M1: 유기농 흑미 ( ) | N1: 유기농 차조 ( ) | O1: 유기농 서리태 ( ) | P1: 유기농 발아현미 ( ) | Q1: 유기농 쥐눈이콩 ( ) | R1: 유기농 수수 ( ) | S1: 소면 ( ) | T1: 중면 ( ) | U1: 칼국수 ( )
C2: 10kg | D2: 1kg | E2: 10kg | F2: 1kg | H2: 1kg | I2: 1kg | J2: 1kg | K2: 1kg | L2: 1kg | M2: 1kg | N2: 1kg | O2: 1kg | P2: 1kg | Q2: 1kg | R2: 1kg | S2: 1kg | T2: 1kg | U2: 1kg
A3: 업체 | B3: 품목별 소계 | C3: =C31+C58+C67 -> 5 | D3: =D31+D58+D67 -> 0 | E3: =E31+E58+E67 -> 0 | F3: =F31+F58+F67 -> 0 | H3: =H31+H58+H67 -> 0 | I3: =I31+I58+I67 -> 0 | J3: =J31+J58+J67 -> 0 | K3: =K31+K58+K67 -> 0 | L3: =L31+L58+L67 -> 0 | M3: =M31+M58+M67 -> 0 | N3: =N31+N58+N67 -> 0 | O3: =O31+O58+O67 -> 0 | ... U3: =U31+U58+U67 -> 0 | V3: =D3*10 -> 0 | W3: =F3*10+E3 -> 0 | X3: =SUM(H3:Q3) -> 0 | Y3: =SUM(V3:X3) -> 0
A4: 싱싱 유통 | B4: 계곡중학교
B5: 계곡초등학교
B6: 두륜중학교
B7: 마산초등학교
B8: 북일초등학교
B9: 북평중학교
B10: 북평초등학교
B11: 산이서초등학교
B12: 산이중학교
B13: 산이초등학교
B14: 삼산초등학교
B15: 옥천초등학교
B16: 우수영중학교
... B19: 해남동초등학교
B20: 해오름유치원 | R20: 1
B21: 현산남초등학교
B22: 현산중학교
B23: 현산초등학교
B24: 화산중학교
B25: 화산초등학교
B26: 화원고등학교
B27: 화원중학교
B28: 화원초등학교
B29: 황산중학교
B30: 황산초등학교
C31: =SUM(C4:C30) -> 0 | D31: =SUM(D4:D30) -> 0 | E31: =SUM(E4:E30) -> 0 | F31: =SUM(F4:F30) -> 0 | H31: =SUM(H4:H30) -> 0 | I31: =SUM(I4:I30) -> 0 | J31: =SUM(J4:J30) -> 0 | K31: =SUM(K4:K30) -> 0 | L31: =SUM(L4:L30) -> 0 | M31: =SUM(M4:M30) -> 0 | N31: =SUM(N4:N30) -> 0 | O31: =SUM(O4:O30) -> 0 | ... U31: =SUM(U4:U30) -> 0
A32: 공공 급식 센터 | B32: 공립시등어린이집
B33: 공립한듬어린이집
B34: 공립해남어린이집
B35: 공립해담어린이집
B36: 공립화원어린이집
B37: 동심어린이집
B38: 둘리어린이집
B39: 리틀어린이집
B40: 미래클유치원
B41: 벧엘특수어린이집 | C41: 1
B42: 산이어린이집 | C42: 1
...

Sheet 공장동01.09
A1: 1/9(금) 해남군공공급식 (1/12~1/16 발주량) | C1: 유기농 백미 천지향 ( ) | E1: 유기농 찹쌀 ( ) | H1: 급식센터 입고 | I1: 유기농 찹쌀현미 ( ) | J1: 유기농 현미 ( ) | K1: 유기농 귀리 (박태일) | L1: 유기농 보리 (김종원) | M1: 유기농 기장 (박태일) | N1: 유기농 흑미 (박태일) | O1: 유기농 차조 (신승철) | P1: 유기농 서리태 (이관) | Q1: 유기농 발아현미 (곽해용) | R1: 유기농 쥐눈이콩 (신승철) | S1: 유기농 수수 (윤영식) | T1: 소면 ( ) | U1: 중면 ( ) | V1: 칼국수면 ( )
C2: 10kg | D2: 1kg | E2: 10kg | F2: 1kg | I2: 1kg | J2: 1kg | K2: 1kg | L2: 1kg | M2: 1kg | N2: 1kg | O2: 1kg | P2: 1kg | Q2: 1kg | R2: 1kg | S2: 1kg | T2: 1kg | U2: 1kg | V2: 1kg
A3: 품목별 소계 | C3: =SUM(C4:C19) -> 5 | D3: =SUM(D4:D19) -> 0 | E3: =SUM(E4:E19) -> 0 | F3: =SUM(F4:F19) -> 0 | H3: 품목별 소계 | I3: =SUM(I4:I11) -> 0 | J3: =SUM(J4:J11) -> 0 | K3: =SUM(K4:K11) -> 0 | L3: =SUM(L4:L11) -> 0 | M3: =SUM(M4:M11) -> 0 | N3: =SUM(N4:N11) -> 0 | O3: =SUM(O4:O11) -> 0 | P3: =SUM(P4:P11) -> 0 | ... V3: =SUM(V4:V11) -> 0
A4: 싱싱유통 | C4: ='학교별01.09'!C31 -> 0 | D4: ='학교별01.09'!D31 -> 0 | E4: ='학교별01.09'!E31 -> 0 | F4: ='학교별01.09'!F31 -> 0 | H4: 싱싱유통 | I4: ='학교별01.09'!H31 -> 0 | J4: ='학교별01.09'!I31 -> 0 | K4: ='학교별01.09'!J31 -> 0 | L4: ='학교별01.09'!K31 -> 0 | M4: ='학교별01.09'!L31 -> 0 | N4: ='학교별01.09'!M31 -> 0 | O4: ='학교별01.09'!N31 -> 0 | P4: ='학교별01.09'!O31 -> 0 | ... V4: ='학교별01.09'!U31 -> 0
A7: 공공급식센터 | C7: ='학교별01.09'!C58 -> 5 | D7: ='학교별01.09'!D58 -> 0 | E7: ='학교별01.09'!E58 -> 0 | F7: ='학교별01.09'!F58 -> 0 | H7: 급식센터 | I7: ='학교별01.09'!H58 -> 0 | J7: ='학교별01.09'!I58 -> 0 | K7: ='학교별01.09'!J58 -> 0 | L7: ='학교별01.09'!K58 -> 0 | M7: ='학교별01.09'!L58 -> 0 | N7: ='학교별01.09'!M58 -> 0 | O7: ='학교별01.09'!N58 -> 0 | P7: ='학교별01.09'!O58 -> 0 | ... V7: ='학교별01.09'!U58 -> 0
A10: 땅끝농협 | C10: ='학교별01.09'!C67 -> 0 | D10: ='학교별01.09'!D67 -> 0 | E10: ='학교별01.09'!E67 -> 0 | F10: ='학교별01.09'!F67 -> 0 | H10: 땅끝농협 | I10: ='학교별01.09'!H67 -> 0 | J10: ='학교별01.09'!I67 -> 0 | K10: ='학교별01.09'!J67 -> 0 | L10: ='학교별01.09'!K67 -> 0 | M10: ='학교별01.09'!L67 -> 0 | N10: ='학교별01.09'!M67 -> 0 | O10: ='학교별01.09'!N67 -> 0 | P10: ='학교별01.09'!O67 -> 0 | ... V10: ='학교별01.09'!U67 -> 0

Sheet 학교별01.16
A1: 1/16(금) 해남군공공급식 (1/19~1/23 발주량) | C1: 유기농 백미 ( ) | E1: 유기농 찹쌀 ( ) | H1: 유기농 찹쌀현미 ( ) | I1: 유기농 현미 ( ) | J1: 유기농 귀리 ( ) | K1: 유기농 보리 ( ) | L1: 유기농 기장 ( ) | M1: 유기농 흑미 ( ) | N1: 유기농 차조 ( ) | O1: 유기농 서리태 ( ) | P1: 유기농 발아현미 ( ) | Q1: 유기농 쥐눈이콩 ( ) | R1: 유기농 수수 ( ) | S1: 소면 ( ) | T1: 중면 ( ) | U1: 칼국수 ( )
C2: 10kg | D2: 1kg | E2: 10kg | F2: 1kg | H2: 1kg | I2: 1kg | J2: 1kg | K2: 1kg | L2: 1kg | M2: 1kg | N2: 1kg | O2: 1kg | P2: 1kg | Q2: 1kg | R2: 1kg | S2: 1kg | T2: 1kg | U2: 1kg
A3: 업체 | B3: 품목별 소계 | C3: =C31+C58+C67 -> 9 | D3: =D31+D58+D67 -> 0 | E3: =E31+E58+E67 -> 0 | F3: =F31+F58+F67 -> 0 | H3: =H31+H58+H67 -> 0 | I3: =I31+I58+I67 -> 0 | J3: =J31+J58+J67 -> 0 | K3: =K31+K58+K67 -> 1 | L3: =L31+L58+L67 -> 0 | M3: =M31+M58+M67 -> 0 | N3: =N31+N58+N67 -> 0 | O3: =O31+O58+O67 -> 0 | ... U3: =U31+U58+U67 -> 0 | V3: =D3*10 -> 0 | W3: =F3*10+E3 -> 0 | X3: =SUM(H3:Q3) -> 1 | Y3: =SUM(V3:X3) -> 1
A4: 싱싱 유통 | B4: 계곡중학교
B5: 계곡초등학교
B6: 두륜중학교
B7: 마산초등학교
B8: 북일초등학교
B9: 북평중학교
B10: 북평초등학교
B11: 산이서초등학교
B12: 산이중학교
B13: 산이초등학교
B14: 삼산초등학교
B15: 옥천초등학교
B16: 우수영중학교
... B19: 해남동초등학교
B20: 해오름유치원 | K20: 1
B21: 현산남초등학교
B22: 현산중학교
B23: 현산초등학교
B24: 화산중학교
B25: 화산초등학교
B26: 화원고등학교
B27: 화원중학교
B28: 화원초등학교
B29: 황산중학교
B30: 황산초등학교
C31: =SUM(C4:C30) -> 0 | D31: =SUM(D4:D30) -> 0 | E31: =SUM(E4:E30) -> 0 | F31: =SUM(F4:F30) -> 0 | H31: =SUM(H4:H30) -> 0 | I31: =SUM(I4:I30) -> 0 | J31: =SUM(J4:J30) -> 0 | K31: =SUM(K4:K30) -> 1 | L31: =SUM(L4:L30) -> 0 | M31: =SUM(M4:M30) -> 0 | N31: =SUM(N4:N30) -> 0 | O31: =SUM(O4:O30) -> 0 | ... U31: =SUM(U4:U30) -> 0
A32: 공공 급식 센터 | B32: 공립시등어린이집
B33: 공립한듬어린이집 | C33: 3
B34: 공립해남어린이집
B35: 공립해담어린이집
B36: 공립화원어린이집
B37: 동심어린이집
B38: 둘리어린이집
B39: 리틀어린이집
B40: 미래클유치원
B41: 벧엘특수어린이집 | C41: 2
B42: 산이어린이집 | C42: 1
...

Sheet 공장동01.16
A1: 1/16(금) 해남군공공급식 (1/19~1/23 발주량) | C1: 유기농 백미 천지향 ( ) | E1: 유기농 찹쌀 ( ) | H1: 급식센터 입고 | I1: 유기농 찹쌀현미 ( ) | J1: 유기농 현미 ( ) | K1: 유기농 귀리 (박태일) | L1: 유기농 보리 (김종원) | M1: 유기농 기장 (박태일) | N1: 유기농 흑미 (박태일) | O1: 유기농 차조 (신승철) | P1: 유기농 서리태 (이관) | Q1: 유기농 발아현미 (곽해용) | R1: 유기농 쥐눈이콩 (신승철) | S1: 유기농 수수 (윤영식) | T1: 소면 ( ) | U1: 중면 ( ) | V1: 칼국수면 ( )
C2: 10kg | D2: 1kg | E2: 10kg | F2: 1kg | I2: 1kg | J2: 1kg | K2: 1kg | L2: 1kg | M2: 1kg | N2: 1kg | O2: 1kg | P2: 1kg | Q2: 1kg | R2: 1kg | S2: 1kg | T2: 1kg | U2: 1kg | V2: 1kg
A3: 품목별 소계 | C3: =SUM(C4:C19) -> 9 | D3: =SUM(D4:D19) -> 0 | E3: =SUM(E4:E19) -> 0 | F3: =SUM(F4:F19) -> 0 | H3: 품목별 소계 | I3: =SUM(I4:I11) -> 0 | J3: =SUM(J4:J11) -> 0 | K3: =SUM(K4:K11) -> 0 | L3: =SUM(L4:L11) -> 1 | M3: =SUM(M4:M11) -> 0 | N3: =SUM(N4:N11) -> 0 | O3: =SUM(O4:O11) -> 0 | P3: =SUM(P4:P11) -> 0 | ... V3: =SUM(V4:V11) -> 0
A4: 싱싱유통 | C4: ='학교별01.16'!C31 -> 0 | D4: ='학교별01.16'!D31 -> 0 | E4: ='학교별01.16'!E31 -> 0 | F4: ='학교별01.16'!F31 -> 0 | H4: 싱싱유통 | I4: ='학교별01.16'!H31 -> 0 | J4: ='학교별01.16'!I31 -> 0 | K4: ='학교별01.16'!J31 -> 0 | L4: ='학교별01.16'!K31 -> 1 | M4: ='학교별01.16'!L31 -> 0 | N4: ='학교별01.16'!M31 -> 0 | O4: ='학교별01.16'!N31 -> 0 | P4: ='학교별01.16'!O31 -> 0 | ... V4: ='학교별01.16'!U31 -> 0
A7: 공공급식센터 | C7: ='학교별01.16'!C58 -> 9 | D7: ='학교별01.16'!D58 -> 0 | E7: ='학교별01.16'!E58 -> 0 | F7: ='학교별01.16'!F58 -> 0 | H7: 급식센터 | I7: ='학교별01.16'!H58 -> 0 | J7: ='학교별01.16'!I58 -> 0 | K7: ='학교별01.16'!J58 -> 0 | L7: ='학교별01.16'!K58 -> 0 | M7: ='학교별01.16'!L58 -> 0 | N7: ='학교별01.16'!M58 -> 0 | O7: ='학교별01.16'!N58 -> 0 | P7: ='학교별01.16'!O58 -> 0 | ... V7: ='학교별01.16'!U58 -> 0
A10: 땅끝농협 | C10: ='학교별01.16'!C67 -> 0 | D10: ='학교별01.16'!D67 -> 0 | E10: ='학교별01.16'!E67 -> 0 | F10: ='학교별01.16'!F67 -> 0 | H10: 땅끝농협 | I10: ='학교별01.16'!H67 -> 0 | J10: ='학교별01.16'!I67 -> 0 | K10: ='학교별01.16'!J67 -> 0 | L10: ='학교별01.16'!K67 -> 0 | M10: ='학교별01.16'!L67 -> 0 | N10: ='학교별01.16'!M67 -> 0 | O10: ='학교별01.16'!N67 -> 0 | P10: ='학교별01.16'!O67 -> 0 | ... V10: ='학교별01.16'!U67 -> 0

Sheet 학교별01.23
A1: 1/23(금) 해남군공공급식 (1/26~1/30 발주량) | C1: 유기농 백미 ( ) | E1: 유기농 찹쌀 ( ) | H1: 유기농 찹쌀현미 ( ) | I1: 유기농 현미 ( ) | J1: 유기농 귀리 ( ) | K1: 유기농 보리 ( ) | L1: 유기농 기장 ( ) | M1: 유기농 흑미 ( ) | N1: 유기농 차조 ( ) | O1: 유기농 서리태 ( ) | P1: 유기농 발아현미 ( ) | Q1: 유기농 쥐눈이콩 ( ) | R1: 유기농 수수 ( ) | S1: 소면 ( ) | T1: 중면 ( ) | U1: 칼국수 ( )
C2: 10kg | D2: 1kg | E2: 10kg | F2: 1kg | H2: 1kg | I2: 1kg | J2: 1kg | K2: 1kg | L2: 1kg | M2: 1kg | N2: 1kg | O2: 1kg | P2: 1kg | Q2: 1kg | R2: 1kg | S2: 1kg | T2: 1kg | U2: 1kg
A3: 업체 | B3: 품목별 소계 | C3: =C31+C58+C67 -> 9 | D3: =D31+D58+D67 -> 0 | E3: =E31+E58+E67 -> 0 | F3: =F31+F58+F67 -> 0 | H3: =H31+H58+H67 -> 0 | I3: =I31+I58+I67 -> 0 | J3: =J31+J58+J67 -> 1 | K3: =K31+K58+K67 -> 0 | L3: =L31+L58+L67 -> 0 | M3: =M31+M58+M67 -> 0 | N3: =N31+N58+N67 -> 1 | O3: =O31+O58+O67 -> 0 | ... U3: =U31+U58+U67 -> 0 | V3: =D3*10 -> 0 | W3: =F3*10+E3 -> 0 | X3: =SUM(H3:Q3) -> 2 | Y3: =SUM(V3:X3) -> 2
A4: 싱싱 유통 | B4: 계곡중학교
B5: 계곡초등학교
B6: 두륜중학교
B7: 마산초등학교
B8: 북일초등학교
B9: 북평중학교
B10: 북평초등학교
B11: 산이서초등학교
B12: 산이중학교
B13: 산이초등학교
B14: 삼산초등학교
B15: 옥천초등학교
B16: 우수영중학교
... B19: 해남동초등학교
B20: 해오름유치원 | J20: 1 | N20: 1
B21: 현산남초등학교
B22: 현산중학교
B23: 현산초등학교
B24: 화산중학교
B25: 화산초등학교
B26: 화원고등학교
B27: 화원중학교
B28: 화원초등학교
B29: 황산중학교
B30: 황산초등학교
C31: =SUM(C4:C30) -> 0 | D31: =SUM(D4:D30) -> 0 | E31: =SUM(E4:E30) -> 0 | F31: =SUM(F4:F30) -> 0 | H31: =SUM(H4:H30) -> 0 | I31: =SUM(I4:I30) -> 0 | J31: =SUM(J4:J30) -> 1 | K31: =SUM(K4:K30) -> 0 | L31: =SUM(L4:L30) -> 0 | M31: =SUM(M4:M30) -> 0 | N31: =SUM(N4:N30) -> 1 | O31: =SUM(O4:O30) -> 0 | ... U31: =SUM(U4:U30) -> 0
A32: 공공 급식 센터 | B32: 공립시등어린이집
B33: 공립한듬어린이집
B34: 공립해남어린이집
B35: 공립해담어린이집
B36: 공립화원어린이집
B37: 동심어린이집
B38: 둘리어린이집
B39: 리틀어린이집
B40: 미래클유치원
B41: 벧엘특수어린이집 | C41: 1
B42: 산이어린이집
...

Sheet 공장동01.23
A1: 1/23(금) 해남군공공급식 (1/26~1/30 발주량) | C1: 유기농 백미 천지향 ( ) | E1: 유기농 찹쌀 ( ) | H1: 급식센터 입고 | I1: 유기농 찹쌀현미 ( ) | J1: 유기농 현미 ( ) | K1: 유기농 귀리 (박태일) | L1: 유기농 보리 (김종원) | M1: 유기농 기장 (박태일) | N1: 유기농 흑미 (박태일) | O1: 유기농 차조 (신승철) | P1: 유기농 서리태 (이관) | Q1: 유기농 발아현미 (곽해용) | R1: 유기농 쥐눈이콩 (신승철) | S1: 유기농 수수 (윤영식) | T1: 소면 ( ) | U1: 중면 ( ) | V1: 칼국수면 ( )
C2: 10kg | D2: 1kg | E2: 10kg | F2: 1kg | I2: 1kg | J2: 1kg | K2: 1kg | L2: 1kg | M2: 1kg | N2: 1kg | O2: 1kg | P2: 1kg | Q2: 1kg | R2: 1kg | S2: 1kg | T2: 1kg | U2: 1kg | V2: 1kg
A3: 품목별 소계 | C3: =SUM(C4:C19) -> 9 | D3: =SUM(D4:D19) -> 0 | E3: =SUM(E4:E19) -> 0 | F3: =SUM(F4:F19) -> 0 | H3: 품목별 소계 | I3: =SUM(I4:I11) -> 0 | J3: =SUM(J4:J11) -> 0 | K3: =SUM(K4:K11) -> 1 | L3: =SUM(L4:L11) -> 0 | M3: =SUM(M4:M11) -> 0 | N3: =SUM(N4:N11) -> 0 | O3: =SUM(O4:O11) -> 1 | P3: =SUM(P4:P11) -> 0 | ... V3: =SUM(V4:V11) -> 0
A4: 싱싱유통 | C4: ='학교별01.23'!C31 -> 0 | D4: ='학교별01.23'!D31 -> 0 | E4: ='학교별01.23'!E31 -> 0 | F4: ='학교별01.23'!F31 -> 0 | H4: 싱싱유통 | I4: ='학교별01.23'!H31 -> 0 | J4: ='학교별01.23'!I31 -> 0 | K4: ='학교별01.23'!J31 -> 1 | L4: ='학교별01.23'!K31 -> 0 | M4: ='학교별01.23'!L31 -> 0 | N4: ='학교별01.23'!M31 -> 0 | O4: ='학교별01.23'!N31 -> 1 | P4: ='학교별01.23'!O31 -> 0 | ... V4: ='학교별01.23'!U31 -> 0
A7: 공공급식센터 | C7: ='학교별01.23'!C58 -> 9 | D7: ='학교별01.23'!D58 -> 0 | E7: ='학교별01.23'!E58 -> 0 | F7: ='학교별01.23'!F58 -> 0 | H7: 급식센터 | I7: ='학교별01.23'!H58 -> 0 | J7: ='학교별01.23'!I58 -> 0 | K7: ='학교별01.23'!J58 -> 0 | L7: ='학교별01.23'!K58 -> 0 | M7: ='학교별01.23'!L58 -> 0 | N7: ='학교별01.23'!M58 -> 0 | O7: ='학교별01.23'!N58 -> 0 | P7: ='학교별01.23'!O58 -> 0 | ... V7: ='학교별01.23'!U58 -> 0
A10: 땅끝농협 | C10: ='학교별01.23'!C67 -> 0 | D10: ='학교별01.23'!D67 -> 0 | E10: ='학교별01.23'!E67 -> 0 | F10: ='학교별01.23'!F67 -> 0 | H10: 땅끝농협 | I10: ='학교별01.23'!H67 -> 0 | J10: ='학교별01.23'!I67 -> 0 | K10: ='학교별01.23'!J67 -> 0 | L10: ='학교별01.23'!K67 -> 0 | M10: ='학교별01.23'!L67 -> 0 | N10: ='학교별01.23'!M67 -> 0 | O10: ='학교별01.23'!N67 -> 0 | P10: ='학교별01.23'!O67 -> 0 | ... V10: ='학교별01.23'!U67 -> 0

Sheet 학교별01.30
A1: 1/30(금) 해남군공공급식 (2/2~2/6 발주량) | C1: 유기농 백미 ( ) | E1: 유기농 찹쌀 ( ) | H1: 유기농 찹쌀현미 ( ) | I1: 유기농 현미 ( ) | J1: 유기농 귀리 ( ) | K1: 유기농 보리 ( ) | L1: 유기농 기장 ( ) | M1: 유기농 흑미 ( ) | N1: 유기농 차조 ( ) | O1: 유기농 서리태 ( ) | P1: 유기농 발아현미 ( ) | Q1: 유기농 쥐눈이콩 ( ) | R1: 유기농 수수 ( ) | S1: 소면 ( ) | T1: 중면 ( ) | U1: 칼국수 ( )
C2: 10kg | D2: 1kg | E2: 10kg | F2: 1kg | H2: 1kg | I2: 1kg | J2: 1kg | K2: 1kg | L2: 1kg | M2: 1kg | N2: 1kg | O2: 1kg | P2: 1kg | Q2: 1kg | R2: 1kg | S2: 1kg | T2: 1kg | U2: 1kg
A3: 업체 | B3: 품목별 소계 | C3: =C31+C58+C67 -> 39 | D3: =D31+D58+D67 -> 0 | E3: =E31+E58+E67 -> 0 | F3: =F31+F58+F67 -> 0 | H3: =H31+H58+H67 -> 0 | I3: =I31+I58+I67 -> 0 | J3: =J31+J58+J67 -> 0 | K3: =K31+K58+K67 -> 0 | L3: =L31+L58+L67 -> 1 | M3: =M31+M58+M67 -> 1 | N3: =N31+N58+N67 -> 0 | O3: =O31+O58+O67 -> 0 | ... U3: =U31+U58+U67 -> 0 | V3: =D3*10 -> 0 | W3: =F3*10+E3 -> 0 | X3: =SUM(H3:Q3) -> 2 | Y3: =SUM(V3:X3) -> 2
A4: 싱싱 유통 | B4: 계곡중학교
B5: 계곡초등학교
B6: 두륜중학교
B7: 마산초등학교
B8: 북일초등학교
B9: 북평중학교
B10: 북평초등학교
B11: 산이서초등학교
B12: 산이중학교
B13: 산이초등학교
B14: 삼산초등학교
B15: 옥천초등학교
B16: 우수영중학교
... B30: 황산초등학교
C31: =SUM(C4:C30) -> 0 | D31: =SUM(D4:D30) -> 0 | E31: =SUM(E4:E30) -> 0 | F31: =SUM(F4:F30) -> 0 | H31: =SUM(H4:H30) -> 0 | I31: =SUM(I4:I30) -> 0 | J31: =SUM(J4:J30) -> 0 | K31: =SUM(K4:K30) -> 0 | L31: =SUM(L4:L30) -> 0 | M31: =SUM(M4:M30) -> 0 | N31: =SUM(N4:N30) -> 0 | O31: =SUM(O4:O30) -> 0 | ... U31: =SUM(U4:U30) -> 0
A32: 공공 급식 센터 | B32: 공립시등어린이집
B33: 공립한듬어린이집 | C33: 4
B34: 공립해남어린이집 | C34: 2
B35: 공립해담어린이집
B36: 공립화원어린이집
B37: 동심어린이집 | C37: 2
B38: 둘리어린이집
B39: 리틀어린이집
B40: 미래클유치원
B41: 벧엘특수어린이집 | C41: 2
B42: 산이어린이집 | C42: 1
B43: 색동어린이집 | C43: 2
B44: 서림어린이집
B45: 신생어린이집
B46: 아트빌어린이집 | C46: 20
B47: 예닮어린이집 | C47: 1
B48: 예찬어린이집 | C48: 5 | L48: 1
B49: 천진어린이집
B50: 코아루다사랑어린이집
B51: 해남복지어린이집
B52: 해남원광어린이집
B53: 해남원광유치원
...

Sheet 공장동01.30
A1: 1/30(금) 해남군공공급식 (2/2~2/6 발주량) | C1: 유기농 백미 천지향 ( ) | E1: 유기농 찹쌀 ( ) | H1: 급식센터 입고 | I1: 유기농 찹쌀현미 ( ) | J1: 유기농 현미 ( ) | K1: 유기농 귀리 (박태일) | L1: 유기농 보리 (김종원) | M1: 유기농 기장 (박태일) | N1: 유기농 흑미 (박태일) | O1: 유기농 차조 (신승철) | P1: 유기농 서리태 (이관) | Q1: 유기농 발아현미 (곽해용) | R1: 유기농 쥐눈이콩 (신승철) | S1: 유기농 수수 (윤영식) | T1: 소면 ( ) | U1: 중면 ( ) | V1: 칼국수면 ( )
C2: 10kg | D2: 1kg | E2: 10kg | F2: 1kg | I2: 1kg | J2: 1kg | K2: 1kg | L2: 1kg | M2: 1kg | N2: 1kg | O2: 1kg | P2: 1kg | Q2: 1kg | R2: 1kg | S2: 1kg | T2: 1kg | U2: 1kg | V2: 1kg
A3: 품목별 소계 | C3: =SUM(C4:C19) -> 39 | D3: =SUM(D4:D19) -> 0 | E3: =SUM(E4:E19) -> 0 | F3: =SUM(F4:F19) -> 0 | H3: 품목별 소계 | I3: =SUM(I4:I11) -> 0 | J3: =SUM(J4:J11) -> 0 | K3: =SUM(K4:K11) -> 0 | L3: =SUM(L4:L11) -> 0 | M3: =SUM(M4:M11) -> 1 | N3: =SUM(N4:N11) -> 1 | O3: =SUM(O4:O11) -> 0 | P3: =SUM(P4:P11) -> 0 | ... V3: =SUM(V4:V11) -> 0
A4: 싱싱유통 | C4: ='학교별01.30'!C31 -> 0 | D4: ='학교별01.30'!D31 -> 0 | E4: ='학교별01.30'!E31 -> 0 | F4: ='학교별01.30'!F31 -> 0 | H4: 싱싱유통 | I4: ='학교별01.30'!H31 -> 0 | J4: ='학교별01.30'!I31 -> 0 | K4: ='학교별01.30'!J31 -> 0 | L4: ='학교별01.30'!K31 -> 0 | M4: ='학교별01.30'!L31 -> 0 | N4: ='학교별01.30'!M31 -> 0 | O4: ='학교별01.30'!N31 -> 0 | P4: ='학교별01.30'!O31 -> 0 | ... V4: ='학교별01.30'!U31 -> 0
A7: 공공급식센터 | C7: ='학교별01.30'!C58 -> 39 | D7: ='학교별01.30'!D58 -> 0 | E7: ='학교별01.30'!E58 -> 0 | F7: ='학교별01.30'!F58 -> 0 | H7: 급식센터 | I7: ='학교별01.30'!H58 -> 0 | J7: ='학교별01.30'!I58 -> 0 | K7: ='학교별01.30'!J58 -> 0 | L7: ='학교별01.30'!K58 -> 0 | M7: ='학교별01.30'!L58 -> 1 | N7: ='학교별01.30'!M58 -> 0 | O7: ='학교별01.30'!N58 -> 0 | P7: ='학교별01.30'!O58 -> 0 | ... V7: ='학교별01.30'!U58 -> 0
A10: 땅끝농협 | C10: ='학교별01.30'!C67 -> 0 | D10: ='학교별01.30'!D67 -> 0 | E10: ='학교별01.30'!E67 -> 0 | F10: ='학교별01.30'!F67 -> 0 | H10: 땅끝농협 | I10: ='학교별01.30'!H67 -> 0 | J10: ='학교별01.30'!I67 -> 0 | K10: ='학교별01.30'!J67 -> 0 | L10: ='학교별01.30'!K67 -> 0 | M10: ='학교별01.30'!L67 -> 0 | N10: ='학교별01.30'!M67 -> 1 | O10: ='학교별01.30'!N67 -> 0 | P10: ='학교별01.30'!O67 -> 0 | ... V10: ='학교별01.30'!U67 -> 0

Sheet 학교별02.06
A1: 2/6(금) 해남군공공급식 (2/9~2/13 발주량) | C1: 유기농 백미 ( ) | E1: 유기농 찹쌀 ( ) | H1: 유기농 찹쌀현미 ( ) | I1: 유기농 현미 ( ) | J1: 유기농 귀리 ( ) | K1: 유기농 보리 ( ) | L1: 유기농 기장 ( ) | M1: 유기농 흑미 ( ) | N1: 유기농 차조 ( ) | O1: 유기농 서리태 ( ) | P1: 유기농 발아현미 ( ) | Q1: 유기농 쥐눈이콩 ( ) | R1: 유기농 수수 ( ) | S1: 소면 ( ) | T1: 중면 ( ) | U1: 칼국수 ( )
C2: 10kg | D2: 1kg | E2: 10kg | F2: 1kg | H2: 1kg | I2: 1kg | J2: 1kg | K2: 1kg | L2: 1kg | M2: 1kg | N2: 1kg | O2: 1kg | P2: 1kg | Q2: 1kg | R2: 1kg | S2: 1kg | T2: 1kg | U2: 1kg
A3: 업체 | B3: 품목별 소계 | C3: =C31+C58+C67 -> 10 | D3: =D31+D58+D67 -> 0 | E3: =E31+E58+E67 -> 0 | F3: =F31+F58+F67 -> 0 | H3: =H31+H58+H67 -> 0 | I3: =I31+I58+I67 -> 0 | J3: =J31+J58+J67 -> 0 | K3: =K31+K58+K67 -> 0 | L3: =L31+L58+L67 -> 1 | M3: =M31+M58+M67 -> 0 | N3: =N31+N58+N67 -> 0 | O3: =O31+O58+O67 -> 0 | ... U3: =U31+U58+U67 -> 0 | V3: =D3*10 -> 0 | W3: =F3*10+E3 -> 0 | X3: =SUM(H3:Q3) -> 1 | Y3: =SUM(V3:X3) -> 1
A4: 싱싱 유통 | B4: 계곡중학교
B5: 계곡초등학교
B6: 두륜중학교
B7: 마산초등학교
B8: 북일초등학교
B9: 북평중학교
B10: 북평초등학교
B11: 산이서초등학교
B12: 산이중학교
B13: 산이초등학교
B14: 삼산초등학교
B15: 옥천초등학교
B16: 우수영중학교
... B30: 황산초등학교
C31: =SUM(C4:C30) -> 0 | D31: =SUM(D4:D30) -> 0 | E31: =SUM(E4:E30) -> 0 | F31: =SUM(F4:F30) -> 0 | H31: =SUM(H4:H30) -> 0 | I31: =SUM(I4:I30) -> 0 | J31: =SUM(J4:J30) -> 0 | K31: =SUM(K4:K30) -> 0 | L31: =SUM(L4:L30) -> 0 | M31: =SUM(M4:M30) -> 0 | N31: =SUM(N4:N30) -> 0 | O31: =SUM(O4:O30) -> 0 | ... U31: =SUM(U4:U30) -> 0
A32: 공공 급식 센터 | B32: 공립시등어린이집
B33: 공립한듬어린이집 | C33: 2
B34: 공립해남어린이집 | C34: 2 | L34: 1
B35: 공립해담어린이집
B36: 공립화원어린이집
B37: 동심어린이집
B38: 둘리어린이집
B39: 리틀어린이집
B40: 미래클유치원
B41: 벧엘특수어린이집 | C41: 2
B42: 산이어린이집 | C42: 1
B43: 색동어린이집 | C43: 2
B44: 서림어린이집
B45: 신생어린이집
B46: 아트빌어린이집
B47: 예닮어린이집 | C47: 1
B48: 예찬어린이집
B49: 천진어린이집
B50: 코아루다사랑어린이집
B51: 해남복지어린이집
B52: 해남원광어린이집
B53: 해남원광유치원
...

Sheet 공장동02.06
A1: 2/6(금) 해남군공공급식 (2/9~2/13 발주량) | C1: 유기농 백미 천지향 ( ) | E1: 유기농 찹쌀 ( ) | H1: 급식센터 입고 | I1: 유기농 찹쌀현미 ( ) | J1: 유기농 현미 ( ) | K1: 유기농 귀리 (박태일) | L1: 유기농 보리 (김종원) | M1: 유기농 기장 (박태일) | N1: 유기농 흑미 (박태일) | O1: 유기농 차조 (신승철) | P1: 유기농 서리태 (이관) | Q1: 유기농 발아현미 (곽해용) | R1: 유기농 쥐눈이콩 (신승철) | S1: 유기농 수수 (윤영식) | T1: 소면 ( ) | U1: 중면 ( ) | V1: 칼국수면 ( )
C2: 10kg | D2: 1kg | E2: 10kg | F2: 1kg | I2: 1kg | J2: 1kg | K2: 1kg | L2: 1kg | M2: 1kg | N2: 1kg | O2: 1kg | P2: 1kg | Q2: 1kg | R2: 1kg | S2: 1kg | T2: 1kg | U2: 1kg | V2: 1kg
A3: 품목별 소계 | C3: =SUM(C4:C19) -> 10 | D3: =SUM(D4:D19) -> 0 | E3: =SUM(E4:E19) -> 0 | F3: =SUM(F4:F19) -> 0 | H3: 품목별 소계 | I3: =SUM(I4:I11) -> 0 | J3: =SUM(J4:J11) -> 0 | K3: =SUM(K4:K11) -> 0 | L3: =SUM(L4:L11) -> 0 | M3: =SUM(M4:M11) -> 1 | N3: =SUM(N4:N11) -> 0 | O3: =SUM(O4:O11) -> 0 | P3: =SUM(P4:P11) -> 0 | ... V3: =SUM(V4:V11) -> 0
A4: 싱싱유통 | C4: ='학교별02.06'!C31 -> 0 | D4: ='학교별02.06'!D31 -> 0 | E4: ='학교별02.06'!E31 -> 0 | F4: ='학교별02.06'!F31 -> 0 | H4: 싱싱유통 | I4: ='학교별02.06'!H31 -> 0 | J4: ='학교별02.06'!I31 -> 0 | K4: ='학교별02.06'!J31 -> 0 | L4: ='학교별02.06'!K31 -> 0 | M4: ='학교별02.06'!L31 -> 0 | N4: ='학교별02.06'!M31 -> 0 | O4: ='학교별02.06'!N31 -> 0 | P4: ='학교별02.06'!O31 -> 0 | ... V4: ='학교별02.06'!U31 -> 0
A7: 공공급식센터 | C7: ='학교별02.06'!C58 -> 10 | D7: ='학교별02.06'!D58 -> 0 | E7: ='학교별02.06'!E58 -> 0 | F7: ='학교별02.06'!F58 -> 0 | H7: 급식센터 | I7: ='학교별02.06'!H58 -> 0 | J7: ='학교별02.06'!I58 -> 0 | K7: ='학교별02.06'!J58 -> 0 | L7: ='학교별02.06'!K58 -> 0 | M7: ='학교별02.06'!L58 -> 1 | N7: ='학교별02.06'!M58 -> 0 | O7: ='학교별02.06'!N58 -> 0 | P7: ='학교별02.06'!O58 -> 0 | ... V7: ='학교별02.06'!U58 -> 0
A10: 땅끝농협 | C10: ='학교별02.06'!C67 -> 0 | D10: ='학교별02.06'!D67 -> 0 | E10: ='학교별02.06'!E67 -> 0 | F10: ='학교별02.06'!F67 -> 0 | H10: 땅끝농협 | I10: ='학교별02.06'!H67 -> 0 | J10: ='학교별02.06'!I67 -> 0 | K10: ='학교별02.06'!J67 -> 0 | L10: ='학교별02.06'!K67 -> 0 | M10: ='학교별02.06'!L67 -> 0 | N10: ='학교별02.06'!M67 -> 0 | O10: ='학교별02.06'!N67 -> 0 | P10: ='학교별02.06'!O67 -> 0 | ... V10: ='학교별02.06'!U67 -> 0

Sheet 학교별02.13
A1: 2/13(금) 해남군공공급식 (2/16~2/20 발주량) | C1: 유기농 백미 ( ) | E1: 유기농 찹쌀 ( ) | H1: 유기농 찹쌀현미 ( ) | I1: 유기농 현미 ( ) | J1: 유기농 귀리 ( ) | K1: 유기농 보리 ( ) | L1: 유기농 기장 ( ) | M1: 유기농 흑미 ( ) | N1: 유기농 차조 ( ) | O1: 유기농 서리태 ( ) | P1: 유기농 발아현미 ( ) | Q1: 유기농 쥐눈이콩 ( ) | R1: 유기농 수수 ( ) | S1: 소면 ( ) | T1: 중면 ( ) | U1: 칼국수 ( )
C2: 10kg | D2: 1kg | E2: 10kg | F2: 1kg | H2: 1kg | I2: 1kg | J2: 1kg | K2: 1kg | L2: 1kg | M2: 1kg | N2: 1kg | O2: 1kg | P2: 1kg | Q2: 1kg | R2: 1kg | S2: 1kg | T2: 1kg | U2: 1kg
A3: 업체 | B3: 품목별 소계 | C3: =C31+C58+C67 -> 4 | D3: =D31+D58+D67 -> 0 | E3: =E31+E58+E67 -> 0 | F3: =F31+F58+F67 -> 0 | H3: =H31+H58+H67 -> 0 | I3: =I31+I58+I67 -> 0 | J3: =J31+J58+J67 -> 0 | K3: =K31+K58+K67 -> 0 | L3: =L31+L58+L67 -> 0 | M3: =M31+M58+M67 -> 0 | N3: =N31+N58+N67 -> 0 | O3: =O31+O58+O67 -> 0 | ... U3: =U31+U58+U67 -> 0 | V3: =D3*10 -> 0 | W3: =F3*10+E3 -> 0 | X3: =SUM(H3:Q3) -> 0 | Y3: =SUM(V3:X3) -> 0
A4: 싱싱 유통 | B4: 계곡중학교
B5: 계곡초등학교
B6: 두륜중학교
B7: 마산초등학교
B8: 북일초등학교
B9: 북평중학교
B10: 북평초등학교
B11: 산이서초등학교
B12: 산이중학교
B13: 산이초등학교
B14: 삼산초등학교
B15: 옥천초등학교
B16: 우수영중학교
... B30: 황산초등학교
C31: =SUM(C4:C30) -> 0 | D31: =SUM(D4:D30) -> 0 | E31: =SUM(E4:E30) -> 0 | F31: =SUM(F4:F30) -> 0 | H31: =SUM(H4:H30) -> 0 | I31: =SUM(I4:I30) -> 0 | J31: =SUM(J4:J30) -> 0 | K31: =SUM(K4:K30) -> 0 | L31: =SUM(L4:L30) -> 0 | M31: =SUM(M4:M30) -> 0 | N31: =SUM(N4:N30) -> 0 | O31: =SUM(O4:O30) -> 0 | ... U31: =SUM(U4:U30) -> 0
A32: 공공 급식 센터 | B32: 공립시등어린이집
B33: 공립한듬어린이집
B34: 공립해남어린이집
B35: 공립해담어린이집 | C35: 2
B36: 공립화원어린이집
B37: 동심어린이집
B38: 둘리어린이집
B39: 리틀어린이집
B40: 미래클유치원
B41: 벧엘특수어린이집
B42: 산이어린이집 | C42: 1
B43: 색동어린이집
B44: 서림어린이집
B45: 신생어린이집
B46: 아트빌어린이집
B47: 예닮어린이집 | C47: 1
B48: 예찬어린이집
B49: 천진어린이집
B50: 코아루다사랑어린이집
B51: 해남복지어린이집
B52: 해남원광어린이집
B53: 해남원광유치원
...

Sheet 공장동02.13
A1: 2/13(금) 해남군공공급식 (2/16~2/20 발주량) | C1: 유기농 백미 천지향 ( ) | E1: 유기농 찹쌀 ( ) | H1: 급식센터 입고 | I1: 유기농 찹쌀현미 ( ) | J1: 유기농 현미 ( ) | K1: 유기농 귀리 (박태일) | L1: 유기농 보리 (김종원) | M1: 유기농 기장 (박태일) | N1: 유기농 흑미 (박태일) | O1: 유기농 차조 (임정옥) | P1: 유기농 팥 (신승철) | Q1: 유기농 발아현미 (곽해용) | R1: 유기농 쥐눈이콩 (신승철) | S1: 유기농 수수 (윤영식) | T1: 소면 ( ) | U1: 중면 ( ) | V1: 칼국수면 ( )
C2: 10kg | D2: 1kg | E2: 10kg | F2: 1kg | I2: 1kg | J2: 1kg | K2: 1kg | L2: 1kg | M2: 1kg | N2: 1kg | O2: 1kg | P2: 1kg | Q2: 1kg | R2: 1kg | S2: 1kg | T2: 1kg | U2: 1kg | V2: 1kg
A3: 품목별 소계 | C3: =SUM(C4:C19) -> 4 | D3: =SUM(D4:D19) -> 0 | E3: =SUM(E4:E19) -> 0 | F3: =SUM(F4:F19) -> 0 | H3: 품목별 소계 | I3: =SUM(I4:I11) -> 0 | J3: =SUM(J4:J11) -> 0 | K3: =SUM(K4:K11) -> 0 | L3: =SUM(L4:L11) -> 0 | M3: =SUM(M4:M11) -> 0 | N3: =SUM(N4:N11) -> 0 | O3: =SUM(O4:O11) -> 0 | P3: =SUM(P4:P11) -> 0 | ... V3: =SUM(V4:V11) -> 0
A4: 싱싱유통 | C4: ='학교별02.13'!C31 -> 0 | D4: ='학교별02.13'!D31 -> 0 | E4: ='학교별02.13'!E31 -> 0 | F4: ='학교별02.13'!F31 -> 0 | H4: 싱싱유통 | I4: ='학교별02.13'!H31 -> 0 | J4: ='학교별02.13'!I31 -> 0 | K4: ='학교별02.13'!J31 -> 0 | L4: ='학교별02.13'!K31 -> 0 | M4: ='학교별02.13'!L31 -> 0 | N4: ='학교별02.13'!M31 -> 0 | O4: ='학교별02.13'!N31 -> 0 | P4: ='학교별02.13'!O31 -> 0 | ... V4: ='학교별02.13'!U31 -> 0
A7: 공공급식센터 | C7: ='학교별02.13'!C58 -> 4 | D7: ='학교별02.13'!D58 -> 0 | E7: ='학교별02.13'!E58 -> 0 | F7: ='학교별02.13'!F58 -> 0 | H7: 급식센터 | I7: ='학교별02.13'!H58 -> 0 | J7: ='학교별02.13'!I58 -> 0 | K7: ='학교별02.13'!J58 -> 0 | L7: ='학교별02.13'!K58 -> 0 | M7: ='학교별02.13'!L58 -> 0 | N7: ='학교별02.13'!M58 -> 0 | O7: ='학교별02.13'!N58 -> 0 | P7: ='학교별02.13'!O58 -> 0 | ... V7: ='학교별02.13'!U58 -> 0
A10: 땅끝농협 | C10: ='학교별02.13'!C67 -> 0 | D10: ='학교별02.13'!D67 -> 0 | E10: ='학교별02.13'!E67 -> 0 | F10: ='학교별02.13'!F67 -> 0 | H10: 땅끝농협 | I10: ='학교별02.13'!H67 -> 0 | J10: ='학교별02.13'!I67 -> 0 | K10: ='학교별02.13'!J67 -> 0 | L10: ='학교별02.13'!K67 -> 0 | M10: ='학교별02.13'!L67 -> 0 | N10: ='학교별02.13'!M67 -> 0 | O10: ='학교별02.13'!N67 -> 0 | P10: ='학교별02.13'!O67 -> 0 | ... V10: ='학교별02.13'!U67 -> 0

Sheet 학교별02.20
A1: 2/20(금) 해남군공공급식 (2/23~2/27 발주량) | C1: 유기농 백미 ( ) | E1: 유기농 찹쌀 ( ) | H1: 유기농 찹쌀현미 ( ) | I1: 유기농 현미 ( ) | J1: 유기농 귀리 ( ) | K1: 유기농 보리 ( ) | L1: 유기농 기장 ( ) | M1: 유기농 흑미 ( ) | N1: 유기농 차조 ( ) | O1: 유기농 서리태 ( ) | P1: 유기농 발아현미 ( ) | Q1: 유기농 쥐눈이콩 ( ) | R1: 유기농 수수 ( ) | S1: 소면 ( ) | T1: 중면 ( ) | U1: 칼국수 ( )
C2: 10kg | D2: 1kg | E2: 10kg | F2: 1kg | H2: 1kg | I2: 1kg | J2: 1kg | K2: 1kg | L2: 1kg | M2: 1kg | N2: 1kg | O2: 1kg | P2: 1kg | Q2: 1kg | R2: 1kg | S2: 1kg | T2: 1kg | U2: 1kg
A3: 업체 | B3: 품목별 소계 | C3: =C31+C58+C67 -> 11 | D3: =D31+D58+D67 -> 0 | E3: =E31+E58+E67 -> 0 | F3: =F31+F58+F67 -> 0 | H3: =H31+H58+H67 -> 0 | I3: =I31+I58+I67 -> 0 | J3: =J31+J58+J67 -> 0 | K3: =K31+K58+K67 -> 0 | L3: =L31+L58+L67 -> 0 | M3: =M31+M58+M67 -> 0 | N3: =N31+N58+N67 -> 0 | O3: =O31+O58+O67 -> 0 | ... U3: =U31+U58+U67 -> 0 | V3: =D3*10 -> 0 | W3: =F3*10+E3 -> 0 | X3: =SUM(H3:Q3) -> 0 | Y3: =SUM(V3:X3) -> 0
A4: 싱싱 유통 | B4: 계곡중학교
B5: 계곡초등학교
B6: 두륜중학교
B7: 마산초등학교
B8: 북일초등학교
B9: 북평중학교
B10: 북평초등학교
B11: 산이서초등학교
B12: 산이중학교
B13: 산이초등학교
B14: 삼산초등학교
B15: 옥천초등학교
B16: 우수영중학교
... B30: 황산초등학교
C31: =SUM(C4:C30) -> 0 | D31: =SUM(D4:D30) -> 0 | E31: =SUM(E4:E30) -> 0 | F31: =SUM(F4:F30) -> 0 | H31: =SUM(H4:H30) -> 0 | I31: =SUM(I4:I30) -> 0 | J31: =SUM(J4:J30) -> 0 | K31: =SUM(K4:K30) -> 0 | L31: =SUM(L4:L30) -> 0 | M31: =SUM(M4:M30) -> 0 | N31: =SUM(N4:N30) -> 0 | O31: =SUM(O4:O30) -> 0 | ... U31: =SUM(U4:U30) -> 0
A32: 공공 급식 센터 | B32: 공립시등어린이집
B33: 공립한듬어린이집
B34: 공립해남어린이집 | C34: 2
B35: 공립해담어린이집
B36: 공립화원어린이집
B37: 동심어린이집
B38: 둘리어린이집
B39: 리틀어린이집
B40: 미래클유치원
B41: 벧엘특수어린이집 | C41: 2
B42: 산이어린이집
B43: 색동어린이집 | C43: 2
B44: 서림어린이집
B45: 신생어린이집 | C45: 5
B46: 아트빌어린이집
B47: 예닮어린이집
B48: 예찬어린이집
B49: 천진어린이집
B50: 코아루다사랑어린이집
B51: 해남복지어린이집
B52: 해남원광어린이집
B53: 해남원광유치원
...

Sheet 공장동02.20
A1: 2/20(금) 해남군공공급식 (2/23~2/27 발주량) | C1: 유기농 백미 천지향 ( ) | E1: 유기농 찹쌀 ( ) | H1: 급식센터 입고 | I1: 유기농 찹쌀현미 ( ) | J1: 유기농 현미 ( ) | K1: 유기농 귀리 (박태일) | L1: 유기농 보리 (김종원) | M1: 유기농 기장 (박태일) | N1: 유기농 흑미 (박태일) | O1: 유기농 차조 (임정옥) | P1: 유기농 팥 (신승철) | Q1: 유기농 발아현미 (곽해용) | R1: 유기농 쥐눈이콩 (신승철) | S1: 유기농 수수 (윤영식) | T1: 소면 ( ) | U1: 중면 ( ) | V1: 칼국수면 ( )
C2: 10kg | D2: 1kg | E2: 10kg | F2: 1kg | I2: 1kg | J2: 1kg | K2: 1kg | L2: 1kg | M2: 1kg | N2: 1kg | O2: 1kg | P2: 1kg | Q2: 1kg | R2: 1kg | S2: 1kg | T2: 1kg | U2: 1kg | V2: 1kg
A3: 품목별 소계 | C3: =SUM(C4:C19) -> 11 | D3: =SUM(D4:D19) -> 0 | E3: =SUM(E4:E19) -> 0 | F3: =SUM(F4:F19) -> 0 | H3: 품목별 소계 | I3: =SUM(I4:I11) -> 0 | J3: =SUM(J4:J11) -> 0 | K3: =SUM(K4:K11) -> 0 | L3: =SUM(L4:L11) -> 0 | M3: =SUM(M4:M11) -> 0 | N3: =SUM(N4:N11) -> 0 | O3: =SUM(O4:O11) -> 0 | P3: =SUM(P4:P11) -> 0 | ... V3: =SUM(V4:V11) -> 0
A4: 싱싱유통 | C4: ='학교별02.20'!C31 -> 0 | D4: ='학교별02.20'!D31 -> 0 | E4: ='학교별02.20'!E31 -> 0 | F4: ='학교별02.20'!F31 -> 0 | H4: 싱싱유통 | I4: ='학교별02.20'!H31 -> 0 | J4: ='학교별02.20'!I31 -> 0 | K4: ='학교별02.20'!J31 -> 0 | L4: ='학교별02.20'!K31 -> 0 | M4: ='학교별02.20'!L31 -> 0 | N4: ='학교별02.20'!M31 -> 0 | O4: ='학교별02.20'!N31 -> 0 | P4: ='학교별02.20'!O31 -> 0 | ... V4: ='학교별02.20'!U31 -> 0
A7: 공공급식센터 | C7: ='학교별02.20'!C58 -> 11 | D7: ='학교별02.20'!D58 -> 0 | E7: ='학교별02.20'!E58 -> 0 | F7: ='학교별02.20'!F58 -> 0 | H7: 급식센터 | I7: ='학교별02.20'!H58 -> 0 | J7: ='학교별02.20'!I58 -> 0 | K7: ='학교별02.20'!J58 -> 0 | L7: ='학교별02.20'!K58 -> 0 | M7: ='학교별02.20'!L58 -> 0 | N7: ='학교별02.20'!M58 -> 0 | O7: ='학교별02.20'!N58 -> 0 | P7: ='학교별02.20'!O58 -> 0 | ... V7: ='학교별02.20'!U58 -> 0
A10: 땅끝농협 | C10: ='학교별02.20'!C67 -> 0 | D10: ='학교별02.20'!D67 -> 0 | E10: ='학교별02.20'!E67 -> 0 | F10: ='학교별02.20'!F67 -> 0 | H10: 땅끝농협 | I10: ='학교별02.20'!H67 -> 0 | J10: ='학교별02.20'!I67 -> 0 | K10: ='학교별02.20'!J67 -> 0 | L10: ='학교별02.20'!K67 -> 0 | M10: ='학교별02.20'!L67 -> 0 | N10: ='학교별02.20'!M67 -> 0 | O10: ='학교별02.20'!N67 -> 0 | P10: ='학교별02.20'!O67 -> 0 | ... V10: ='학교별02.20'!U67 -> 0

Sheet 학교별02.27
A1: 2/27(금) 해남군공공급식 (3/3~3/6 발주량) | C1: 유기농 백미 ( ) | E1: 유기농 찹쌀 ( ) | H1: 유기농 찹쌀현미 ( ) | I1: 유기농 현미 ( ) | J1: 유기농 귀리 ( ) | K1: 유기농 보리 ( ) | L1: 유기농 기장 ( ) | M1: 유기농 흑미 ( ) | N1: 유기농 차조 ( ) | O1: 유기농 팥 ( ) | P1: 유기농 발아현미 ( ) | Q1: 유기농 쥐눈이콩 ( ) | R1: 유기농 수수 ( ) | S1: 유기농 서리태 ( ) | T1: ( ) | U1: ( )
C2: 10kg | D2: 1kg | E2: 10kg | F2: 1kg | H2: 1kg | I2: 1kg | J2: 1kg | K2: 1kg | L2: 1kg | M2: 1kg | N2: 1kg | O2: 1kg | P2: 1kg | Q2: 1kg | R2: 1kg | S2: 1kg | T2: 1kg | U2: 1kg
A3: 업체 | B3: 품목별 소계 | C3: =C22+C43+C52+C62 -> 91 | D3: =D22+D43+D52+D62 -> 0 | E3: =E22+E43+E52+E62 -> 16 | F3: =F22+F43+F52+F62 -> 82 | H3: =H22+H43+H52+H62 -> 6 | I3: =I22+I43+I52+I62 -> 2 | J3: =J22+J43+J52+J62 -> 3 | K3: =K22+K43+K52+K62 -> 17 | L3: =L22+L43+L52+L62 -> 9 | M3: =M22+M43+M52+M62 -> 4 | N3: =N22+N43+N52+N62 -> 3 | O3: =O22+O43+O52+O62 -> 8 | ... U3: =U22+U43+U52+U62 -> 0 | V3: =D3*10 -> 0 | W3: =F3*10+E3 -> 836 | X3: =SUM(H3:Q3) -> 52 | Y3: =SUM(V3:X3) -> 888
A4: 싱싱 유통 | B4: 두륜중학교
B5: 마산초등학교 | K5: 1 | L5: 1 | M5: 1
B6: 북일초등학교
B7: 북평중학교
B8: 북평초등학교 | K8: 10
B9: 산이서초등학교
B10: 산이중학교 | K10: 1
B11: 산이초등학교
B12: 우수영중학교 | M12: 1 | O12: 1
B13: 우수영초등학교 | L13: 1 | M13: 1
B14: 해남고등학교
B15: 현산중학교 | N15: 1 | O15: 1 | R15: 1 | S15: 1
B16: 현산초등학교
B17: 화원고등학교
B18: 화원중학교
B19: 화원초등학교 | L19: 1 | O19: 1
B20: 황산중학교 | K20: 1
B21: 황산초등학교
C22: =SUM(C4:C21) -> 0 | D22: =SUM(D4:D21) -> 0 | E22: =SUM(E4:E21) -> 0 | F22: =SUM(F4:F21) -> 0 | H22: =SUM(H4:H21) -> 0 | I22: =SUM(I4:I21) -> 0 | J22: =SUM(J4:J21) -> 0 | K22: =SUM(K4:K21) -> 13 | L22: =SUM(L4:L21) -> 3 | M22: =SUM(M4:M21) -> 3 | N22: =SUM(N4:N21) -> 1 | O22: =SUM(O4:O21) -> 3 | ... U22: =SUM(U4:U21) -> 0
A23: 공공 급식 센터 | B23: 공립해남어린이집 | O23: 1
B24: 공립화원어린이집
B25: 동심어린이집
B26: 리틀어린이집
B27: 미래클유치원 | M27: 1
B28: 벧엘특수어린이집
B29: 산이어린이집 | R29: 1
B30: 색동어린이집
B31: 서림어린이집
B32: 시등어린이집
B33: 신생어린이집 | N33: 1 | O33: 1
B34: 아트빌어린이집
B35: 예닮어린이집
B36: 예찬어린이집
B37: 원광유치원
B38: 천진어린이집
B39: 한듬어린이집
B40: 해남원광어린이집
...

Sheet 공장동02.27
A1: 2/27(금) 해남군공공급식 (3/3~3/6 발주량) | C1: 유기농 백미 천지향 ( ) | E1: 유기농 찹쌀 ( ) | H1: 급식센터 입고 | I1: 유기농 찹쌀현미 ( ) | J1: 유기농 현미 ( ) | K1: 유기농 귀리 (박태일) | L1: 유기농 보리 (김종원) | M1: 유기농 기장 (박태일) | N1: 유기농 흑미 (박태일) | O1: 유기농 차조 (임정옥) | P1: 유기농 팥 (신승철) | Q1: 유기농 발아현미 (곽해용) | R1: 유기농 쥐눈이콩 (신승철) | S1: 유기농 수수 (윤영식) | T1: 유기농 서리태 ( ) | U1: 중면 ( ) | V1: 칼국수면 ( )
C2: 10kg | D2: 1kg | E2: 10kg | F2: 1kg | I2: 1kg | J2: 1kg | K2: 1kg | L2: 1kg | M2: 1kg | N2: 1kg | O2: 1kg | P2: 1kg | Q2: 1kg | R2: 1kg | S2: 1kg | T2: 1kg | U2: 1kg | V2: 1kg
A3: 품목별 소계 | C3: =SUM(C4:C19) -> 91 | D3: =SUM(D4:D19) -> 0 | E3: =SUM(E4:E19) -> 16 | F3: =SUM(F4:F19) -> 82 | H3: 품목별 소계 | I3: =SUM(I4:I14) -> 6 | J3: =SUM(J4:J14) -> 2 | K3: =SUM(K4:K14) -> 3 | L3: =SUM(L4:L14) -> 17 | M3: =SUM(M4:M14) -> 9 | N3: =SUM(N4:N14) -> 4 | O3: =SUM(O4:O14) -> 3 | P3: =SUM(P4:P14) -> 8 | ... U3: =SUM(U4:U14) -> 0 | V3: =SUM(V4:V11) -> 0
A4: 싱싱유통 | C4: ='학교별02.27'!C22 -> 0 | D4: ='학교별02.27'!D22 -> 0 | E4: ='학교별02.27'!E22 -> 0 | F4: ='학교별02.27'!F22 -> 0 | H4: 싱싱유통 | I4: ='학교별02.27'!H22 -> 0 | J4: ='학교별02.27'!I22 -> 0 | K4: ='학교별02.27'!J22 -> 0 | L4: ='학교별02.27'!K22 -> 13 | M4: ='학교별02.27'!L22 -> 3 | N4: ='학교별02.27'!M22 -> 3 | O4: ='학교별02.27'!N22 -> 1 | P4: ='학교별02.27'!O22 -> 3 | ... V4: ='학교별02.27'!U22 -> 0
A7: 공공급식센터 | C7: ='학교별02.27'!C43 -> 0 | D7: ='학교별02.27'!D43 -> 0 | E7: ='학교별02.27'!E43 -> 0 | F7: ='학교별02.27'!F43 -> 0 | H7: 급식센터 | I7: ='학교별02.27'!H43 -> 0 | J7: ='학교별02.27'!I43 -> 0 | K7: ='학교별02.27'!J43 -> 0 | L7: ='학교별02.27'!K43 -> 0 | M7: ='학교별02.27'!L43 -> 0 | N7: ='학교별02.27'!M43 -> 1 | O7: ='학교별02.27'!N43 -> 1 | P7: ='학교별02.27'!O43 -> 2 | ... V7: ='학교별02.27'!U43 -> 0
A10: 땅끝농협 | C10: ='학교별02.27'!C52 -> 19 | D10: ='학교별02.27'!D52 -> 0 | E10: ='학교별02.27'!E52 -> 3 | F10: ='학교별02.27'!F52 -> 5 | H10: 땅끝농협 | I10: ='학교별02.27'!H52 -> 5 | J10: ='학교별02.27'!I52 -> 0 | K10: ='학교별02.27'!J52 -> 0 | L10: ='학교별02.27'!K52 -> 3 | M10: ='학교별02.27'!L52 -> 3 | N10: ='학교별02.27'!M52 -> 0 | O10: ='학교별02.27'!N52 -> 0 | P10: ='학교별02.27'!O52 -> 0 | ... V10: ='학교별02.27'!U52 -> 0
A13: 참솔 | C13: ='학교별02.27'!C62 -> 72 | D13: ='학교별02.27'!D62 -> 0 | E13: ='학교별02.27'!E62 -> 13 | F13: ='학교별02.27'!F62 -> 77 | H13: 참솔 | I13: ='학교별02.27'!H62 -> 1 | J13: ='학교별02.27'!I62 -> 2 | K13: ='학교별02.27'!J62 -> 3 | L13: ='학교별02.27'!K62 -> 1 | M13: ='학교별02.27'!L62 -> 3 | N13: ='학교별02.27'!M62 -> 0 | O13: ='학교별02.27'!N62 -> 1 | P13: ='학교별02.27'!O62 -> 3 | ... V13: ='학교별02.27'!U62 -> 0

Sheet 학교별03.06
A1: 3/6(금) 해남군공공급식 (3/9~3/13 발주량) | C1: 유기농 백미 ( ) | E1: 유기농 찹쌀 ( ) | H1: 유기농 찹쌀현미 ( ) | I1: 유기농 현미 ( ) | J1: 유기농 귀리 ( ) | K1: 유기농 보리 ( ) | L1: 유기농 기장 ( ) | M1: 유기농 흑미 ( ) | N1: 유기농 차조 ( ) | O1: 유기농 팥 ( ) | P1: 유기농 발아현미 ( ) | Q1: 유기농 쥐눈이콩 ( ) | R1: 유기농 수수 ( ) | S1: 유기농 서리태 ( ) | T1: ( ) | U1: ( )
C2: 10kg | D2: 1kg | E2: 10kg | F2: 1kg | H2: 1kg | I2: 1kg | J2: 1kg | K2: 1kg | L2: 1kg | M2: 1kg | N2: 1kg | O2: 1kg | P2: 1kg | Q2: 1kg | R2: 1kg | S2: 1kg | T2: 1kg | U2: 1kg
A3: 업체 | B3: 품목별 소계 | C3: =C22+C43+C52+C62 -> 40 | D3: =D22+D43+D52+D62 -> 0 | E3: =E22+E43+E52+E62 -> 16 | F3: =F22+F43+F52+F62 -> 21 | H3: =H22+H43+H52+H62 -> 6 | I3: =I22+I43+I52+I62 -> 0 | J3: =J22+J43+J52+J62 -> 5 | K3: =K22+K43+K52+K62 -> 5 | L3: =L22+L43+L52+L62 -> 9 | M3: =M22+M43+M52+M62 -> 0 | N3: =N22+N43+N52+N62 -> 4 | O3: =O22+O43+O52+O62 -> 0 | ... U3: =U22+U43+U52+U62 -> 0 | V3: =D3*10 -> 0 | W3: =F3*10+E3 -> 226 | X3: =SUM(H3:Q3) -> 31 | Y3: =SUM(V3:X3) -> 257
A4: 싱싱 유통 | B4: 두륜중학교
B5: 마산초등학교 | K5: 1
B6: 북일초등학교 | N6: 1 | R6: 1
B7: 북평중학교 | K7: 1
B8: 북평초등학교 | J8: 1
B9: 산이서초등학교
B10: 산이중학교 | J10: 1
B11: 산이초등학교 | L11: 1
B12: 우수영중학교 | L12: 1
B13: 우수영초등학교 | R13: 1
B14: 해남고등학교
B15: 현산중학교 | K15: 1
B16: 현산초등학교
B17: 화원고등학교
B18: 화원중학교
B19: 화원초등학교 | R19: 1 | S19: 1
B20: 황산중학교
B21: 황산초등학교
C22: =SUM(C4:C21) -> 0 | D22: =SUM(D4:D21) -> 0 | E22: =SUM(E4:E21) -> 0 | F22: =SUM(F4:F21) -> 0 | H22: =SUM(H4:H21) -> 0 | I22: =SUM(I4:I21) -> 0 | J22: =SUM(J4:J21) -> 2 | K22: =SUM(K4:K21) -> 3 | L22: =SUM(L4:L21) -> 2 | M22: =SUM(M4:M21) -> 0 | N22: =SUM(N4:N21) -> 1 | O22: =SUM(O4:O21) -> 0 | ... U22: =SUM(U4:U21) -> 0
A23: 공공 급식 센터 | B23: 공립해남어린이집 | J23: 1
B24: 공립화원어린이집
B25: 동심어린이집
B26: 리틀어린이집
B27: 미래클유치원 | N27: 1
B28: 벧엘특수어린이집
B29: 산이어린이집
B30: 색동어린이집
B31: 서림어린이집
B32: 시등어린이집
B33: 신생어린이집
B34: 아트빌어린이집
B35: 예닮어린이집
B36: 예찬어린이집
B37: 원광유치원
B38: 천진어린이집
B39: 한듬어린이집
... B42: 화산어린이집
...

Sheet 공장동03.06
A1: 3/6(금) 해남군공공급식 (3/9~3/13 발주량) | C1: 유기농 백미 천지향 ( ) | E1: 유기농 찹쌀 ( ) | H1: 급식센터 입고 | I1: 유기농 찹쌀현미 ( ) | J1: 유기농 현미 ( ) | K1: 유기농 귀리 (박태일) | L1: 유기농 보리 (김종원) | M1: 유기농 기장 (박태일) | N1: 유기농 흑미 (박태일) | O1: 유기농 차조 (임정옥) | P1: 유기농 팥 (신승철) | Q1: 유기농 발아현미 (곽해용) | R1: 유기농 쥐눈이콩 (신승철) | S1: 유기농 수수 (윤영식) | T1: 유기농 서리태 ( ) | U1: 중면 ( ) | V1: 칼국수면 ( )
C2: 10kg | D2: 1kg | E2: 10kg | F2: 1kg | I2: 1kg | J2: 1kg | K2: 1kg | L2: 1kg | M2: 1kg | N2: 1kg | O2: 1kg | P2: 1kg | Q2: 1kg | R2: 1kg | S2: 1kg | T2: 1kg | U2: 1kg | V2: 1kg
A3: 품목별 소계 | C3: =SUM(C4:C19) -> 40 | D3: =SUM(D4:D19) -> 0 | E3: =SUM(E4:E19) -> 16 | F3: =SUM(F4:F19) -> 21 | H3: 품목별 소계 | I3: =SUM(I4:I14) -> 6 | J3: =SUM(J4:J14) -> 0 | K3: =SUM(K4:K14) -> 5 | L3: =SUM(L4:L14) -> 5 | M3: =SUM(M4:M14) -> 9 | N3: =SUM(N4:N14) -> 0 | O3: =SUM(O4:O14) -> 4 | P3: =SUM(P4:P14) -> 0 | ... U3: =SUM(U4:U14) -> 0 | V3: =SUM(V4:V11) -> 0
A4: 싱싱유통 | C4: ='학교별03.06'!C22 -> 0 | D4: ='학교별03.06'!D22 -> 0 | E4: ='학교별03.06'!E22 -> 0 | F4: ='학교별03.06'!F22 -> 0 | H4: 싱싱유통 | I4: ='학교별03.06'!H22 -> 0 | J4: ='학교별03.06'!I22 -> 0 | K4: ='학교별03.06'!J22 -> 2 | L4: ='학교별03.06'!K22 -> 3 | M4: ='학교별03.06'!L22 -> 2 | N4: ='학교별03.06'!M22 -> 0 | O4: ='학교별03.06'!N22 -> 1 | P4: ='학교별03.06'!O22 -> 0 | ... V4: ='학교별03.06'!U22 -> 0
A7: 공공급식센터 | C7: ='학교별03.06'!C43 -> 0 | D7: ='학교별03.06'!D43 -> 0 | E7: ='학교별03.06'!E43 -> 0 | F7: ='학교별03.06'!F43 -> 0 | H7: 급식센터 | I7: ='학교별03.06'!H43 -> 0 | J7: ='학교별03.06'!I43 -> 0 | K7: ='학교별03.06'!J43 -> 1 | L7: ='학교별03.06'!K43 -> 0 | M7: ='학교별03.06'!L43 -> 0 | N7: ='학교별03.06'!M43 -> 0 | O7: ='학교별03.06'!N43 -> 1 | P7: ='학교별03.06'!O43 -> 0 | ... V7: ='학교별03.06'!U43 -> 0
A10: 땅끝농협 | C10: ='학교별03.06'!C52 -> 10 | D10: ='학교별03.06'!D52 -> 0 | E10: ='학교별03.06'!E52 -> 3 | F10: ='학교별03.06'!F52 -> 4 | H10: 땅끝농협 | I10: ='학교별03.06'!H52 -> 5 | J10: ='학교별03.06'!I52 -> 0 | K10: ='학교별03.06'!J52 -> 0 | L10: ='학교별03.06'!K52 -> 0 | M10: ='학교별03.06'!L52 -> 2 | N10: ='학교별03.06'!M52 -> 0 | O10: ='학교별03.06'!N52 -> 0 | P10: ='학교별03.06'!O52 -> 0 | ... V10: ='학교별03.06'!U52 -> 0
A13: 참솔 | C13: ='학교별03.06'!C62 -> 30 | D13: ='학교별03.06'!D62 -> 0 | E13: ='학교별03.06'!E62 -> 13 | F13: ='학교별03.06'!F62 -> 17 | H13: 참솔 | I13: ='학교별03.06'!H62 -> 1 | J13: ='학교별03.06'!I62 -> 0 | K13: ='학교별03.06'!J62 -> 2 | L13: ='학교별03.06'!K62 -> 2 | M13: ='학교별03.06'!L62 -> 5 | N13: ='학교별03.06'!M62 -> 0 | O13: ='학교별03.06'!N62 -> 2 | P13: ='학교별03.06'!O62 -> 0 | ... V13: ='학교별03.06'!U62 -> 0

Sheet 학교별03.13
A1: 3/13(금) 해남군공공급식 (3/16~3/20 발주량) | C1: 유기농 백미 ( ) | E1: 유기농 찹쌀 ( ) | H1: 유기농 찹쌀현미 ( ) | I1: 유기농 현미 ( ) | J1: 유기농 귀리 ( ) | K1: 유기농 보리 ( ) | L1: 유기농 기장 ( ) | M1: 유기농 흑미 ( ) | N1: 유기농 차조 ( ) | O1: 유기농 팥 ( ) | P1: 유기농 발아현미 ( ) | Q1: 유기농 쥐눈이콩 ( ) | R1: 유기농 수수 ( ) | S1: 유기농 서리태 ( ) | T1: ( ) | U1: ( )
C2: 10kg | D2: 1kg | E2: 10kg | F2: 1kg | H2: 1kg | I2: 1kg | J2: 1kg | K2: 1kg | L2: 1kg | M2: 1kg | N2: 1kg | O2: 1kg | P2: 1kg | Q2: 1kg | R2: 1kg | S2: 1kg | T2: 1kg | U2: 1kg
A3: 업체 | B3: 품목별 소계 | C3: =C22+C43+C52+C62 -> 145 | D3: =D22+D43+D52+D62 -> 0 | E3: =E22+E43+E52+E62 -> 34 | F3: =F22+F43+F52+F62 -> 58 | H3: =H22+H43+H52+H62 -> 5 | I3: =I22+I43+I52+I62 -> 0 | J3: =J22+J43+J52+J62 -> 2 | K3: =K22+K43+K52+K62 -> 6 | L3: =L22+L43+L52+L62 -> 12 | M3: =M22+M43+M52+M62 -> 2 | N3: =N22+N43+N52+N62 -> 3 | O3: =O22+O43+O52+O62 -> 0 | ... U3: =U22+U43+U52+U62 -> 0 | V3: =D3*10 -> 0 | W3: =F3*10+E3 -> 614 | X3: =SUM(H3:Q3) -> 30 | Y3: =SUM(V3:X3) -> 644
A4: 싱싱 유통 | B4: 두륜중학교
B5: 마산초등학교 | L5: 1 | M5: 1
B6: 북일초등학교
B7: 북평중학교
B8: 북평초등학교 | L8: 1 | R8: 1
B9: 산이서초등학교
B10: 산이중학교 | L10: 1 | N10: 1
B11: 산이초등학교
B12: 우수영중학교 | N12: 1 | R12: 1
B13: 우수영초등학교
B14: 해남고등학교
B15: 현산중학교
B16: 현산초등학교
B17: 화원고등학교
B18: 화원중학교
B19: 화원초등학교 | J19: 1 | M19: 1
B20: 황산중학교 | J20: 1 | N20: 1 | R20: 1
B21: 황산초등학교 | K21: 1 | R21: 1
C22: =SUM(C4:C21) -> 0 | D22: =SUM(D4:D21) -> 0 | E22: =SUM(E4:E21) -> 0 | F22: =SUM(F4:F21) -> 0 | H22: =SUM(H4:H21) -> 0 | I22: =SUM(I4:I21) -> 0 | J22: =SUM(J4:J21) -> 2 | K22: =SUM(K4:K21) -> 1 | L22: =SUM(L4:L21) -> 3 | M22: =SUM(M4:M21) -> 2 | N22: =SUM(N4:N21) -> 3 | O22: =SUM(O4:O21) -> 0 | ... U22: =SUM(U4:U21) -> 0
A23: 공공 급식 센터 | B23: 공립해남어린이집
B24: 공립화원어린이집
B25: 동심어린이집
B26: 리틀어린이집
B27: 미래클유치원
B28: 벧엘특수어린이집
B29: 산이어린이집
B30: 색동어린이집
B31: 서림어린이집
B32: 시등어린이집
B33: 신생어린이집
B34: 아트빌어린이집
B35: 예닮어린이집
... B42: 화산어린이집
C43: =SUM(C23:C42) -> 0 | D43: =SUM(D23:D42) -> 0 | E43: =SUM(E23:E42) -> 0 | F43: =SUM(F23:F42) -> 0 | H43: =SUM(H23:H42) -> 0 | I43: =SUM(I23:I42) -> 0 | J43: =SUM(J23:J42) -> 0 | K43: =SUM(K23:K42) -> 0 | L43: =SUM(L23:L42) -> 0 | M43: =SUM(M23:M42) -> 0 | N43: =SUM(N23:N42) -> 0 | O43: =SUM(O23:O42) -> 0 | ... U43: =SUM(U23:U42) -> 0
A44: 땅끝 농협 | B44: 서정초등학교 | F44: 4
B45: 송지고등학교 | C45: 10 | L45: 1
B46: 송지중학교 | E46: 3
...

Sheet 공장동03.13
A1: 3/13(금) 해남군공공급식 (3/16~3/20 발주량) | C1: 유기농 백미 천지향 ( ) | E1: 유기농 찹쌀 ( ) | H1: 급식센터 입고 | I1: 유기농 찹쌀현미 ( ) | J1: 유기농 현미 ( ) | K1: 유기농 귀리 (박태일) | L1: 유기농 보리 (김종원) | M1: 유기농 기장 (박태일) | N1: 유기농 흑미 (박태일) | O1: 유기농 차조 (임정옥) | P1: 유기농 팥 (신승철) | Q1: 유기농 발아현미 (곽해용) | R1: 유기농 쥐눈이콩 (신승철) | S1: 유기농 수수 (윤영식) | T1: 유기농 서리태 ( ) | U1: 중면 ( ) | V1: 칼국수면 ( )
C2: 10kg | D2: 1kg | E2: 10kg | F2: 1kg | I2: 1kg | J2: 1kg | K2: 1kg | L2: 1kg | M2: 1kg | N2: 1kg | O2: 1kg | P2: 1kg | Q2: 1kg | R2: 1kg | S2: 1kg | T2: 1kg | U2: 1kg | V2: 1kg
A3: 품목별 소계 | C3: =SUM(C4:C20) -> 97 | D3: =SUM(D4:D20) -> 0 | E3: =SUM(E4:E20) -> 26 | F3: =SUM(F4:F20) -> 58 | H3: 품목별 소계 | I3: =SUM(I4:I15) -> 6 | J3: =SUM(J4:J15) -> 0 | K3: =SUM(K4:K15) -> 2 | L3: =SUM(L4:L15) -> 6 | M3: =SUM(M4:M15) -> 12 | N3: =SUM(N4:N15) -> 2 | O3: =SUM(O4:O15) -> 3 | P3: =SUM(P4:P15) -> 0 | ... U3: =SUM(U4:U15) -> 0 | V3: =SUM(V4:V12) -> 0
A4: 싱싱유통 | C4: ='학교별03.13'!C22 -> 0 | D4: ='학교별03.13'!D22 -> 0 | E4: ='학교별03.13'!E22 -> 0 | F4: ='학교별03.13'!F22 -> 0 | H4: 싱싱유통 | I4: ='학교별03.13'!H22 -> 0 | J4: ='학교별03.13'!I22 -> 0 | K4: ='학교별03.13'!J22 -> 2 | L4: ='학교별03.13'!K22 -> 1 | M4: ='학교별03.13'!L22 -> 3 | N4: ='학교별03.13'!M22 -> 2 | O4: ='학교별03.13'!N22 -> 3 | P4: ='학교별03.13'!O22 -> 0 | ... V4: ='학교별03.13'!U22 -> 0
A7: 공공급식센터 | C7: ='학교별03.13'!C43 -> 0 | D7: ='학교별03.13'!D43 -> 0 | E7: ='학교별03.13'!E43 -> 0 | F7: ='학교별03.13'!F43 -> 0 | H7: 급식센터 | I7: ='학교별03.13'!H43 -> 0 | J7: ='학교별03.13'!I43 -> 0 | K7: ='학교별03.13'!J43 -> 0 | L7: ='학교별03.13'!K43 -> 0 | M7: ='학교별03.13'!L43 -> 0 | N7: ='학교별03.13'!M43 -> 0 | O7: ='학교별03.13'!N43 -> 0 | P7: ='학교별03.13'!O43 -> 0 | ... V7: ='학교별03.13'!U43 -> 0
A10: 땅끝농협 | C10: ='학교별03.13'!C52 -> 81 | D10: ='학교별03.13'!D52 -> 0 | E10: ='학교별03.13'!E52 -> 19 | F10: ='학교별03.13'!F52 -> 9 | H10: 땅끝농협 | I10: ='학교별03.13'!H52 -> 5 | J10: ='학교별03.13'!I52 -> 0 | K10: ='학교별03.13'!J52 -> 0 | L10: ='학교별03.13'!K52 -> 2 | M10: ='학교별03.13'!L52 -> 3 | N10: ='학교별03.13'!M52 -> 0 | O10: ='학교별03.13'!N52 -> 0 | P10: ='학교별03.13'!O52 -> 0 | ... V10: ='학교별03.13'!U52 -> 0
A11: 송지고 보관 요청 | C11: -10
A12: 해남공고 선입고 완료 | C12: -38 | E12: -8
A14: 참솔 | C14: ='학교별03.13'!C62 -> 64 | D14: ='학교별03.13'!D62 -> 0 | E14: ='학교별03.13'!E62 -> 15 | F14: ='학교별03.13'!F62 -> 49 | H14: 참솔 | I14: ='학교별03.13'!H62 -> 0 | J14: ='학교별03.13'!I62 -> 0 | K14: ='학교별03.13'!J62 -> 0 | L14: ='학교별03.13'!K62 -> 3 | M14: ='학교별03.13'!L62 -> 6 | N14: ='학교별03.13'!M62 -> 0 | O14: ='학교별03.13'!N62 -> 0 | P14: ='학교별03.13'!O62 -> 0 | ... V14: ='학교별03.13'!U62 -> 0
A15: 화산초 찰현미 선입고 요청 | I15: 1

Sheet 학교별03.20
A1: 3/20(금) 해남군공공급식 (3/23~3/27 발주량) | C1: 유기농 백미 ( ) | E1: 유기농 찹쌀 ( ) | H1: 유기농 찹쌀현미 ( ) | I1: 유기농 현미 ( ) | J1: 유기농 귀리 ( ) | K1: 유기농 보리 ( ) | L1: 유기농 기장 ( ) | M1: 유기농 흑미 ( ) | N1: 유기농 차조 ( ) | O1: 유기농 팥 ( ) | P1: 유기농 발아현미 ( ) | Q1: 유기농 쥐눈이콩 ( ) | R1: 유기농 수수 ( ) | S1: 유기농 서리태 ( )
C2: 10kg | D2: 1kg | E2: 10kg | F2: 1kg | H2: 1kg | I2: 1kg | J2: 1kg | K2: 1kg | L2: 1kg | M2: 1kg | N2: 1kg | O2: 1kg | P2: 1kg | Q2: 1kg | R2: 1kg | S2: 1kg
A3: 업체 | B3: 품목별 소계 | C3: =C22+C43+C52+C62 -> 54 | D3: =D22+D43+D52+D62 -> 0 | E3: =E22+E43+E52+E62 -> 20 | F3: =F22+F43+F52+F62 -> 20 | H3: =H22+H43+H52+H62 -> 6 | I3: =I22+I43+I52+I62 -> 1 | J3: =J22+J43+J52+J62 -> 6 | K3: =K22+K43+K52+K62 -> 7 | L3: =L22+L43+L52+L62 -> 4 | M3: =M22+M43+M52+M62 -> 2 | N3: =N22+N43+N52+N62 -> 5 | O3: =O22+O43+O52+O62 -> 0 | ... S3: =S22+S43+S52+S62 -> 1 | T3: =D3*10 -> 0 | U3: =F3*10+E3 -> 220 | V3: =SUM(H3:Q3) -> 32 | W3: =SUM(T3:V3) -> 252
A4: 싱싱 유통 | B4: 두륜중학교
B5: 마산초등학교 | K5: 1
B6: 북일초등학교 | K6: 1 | S6: 1
B7: 북평중학교 | K7: 1 | P7: 1
B8: 북평초등학교
B9: 산이서초등학교
B10: 산이중학교
B11: 산이초등학교
B12: 우수영중학교
B13: 우수영초등학교 | M13: 1
B14: 해남고등학교
B15: 현산중학교
B16: 현산초등학교
B17: 화원고등학교
B18: 화원중학교
B19: 화원초등학교
B20: 황산중학교
B21: 황산초등학교 | J21: 1 | L21: 1
C22: =SUM(C4:C21) -> 0 | D22: =SUM(D4:D21) -> 0 | E22: =SUM(E4:E21) -> 0 | F22: =SUM(F4:F21) -> 0 | H22: =SUM(H4:H21) -> 0 | I22: =SUM(I4:I21) -> 0 | J22: =SUM(J4:J21) -> 1 | K22: =SUM(K4:K21) -> 3 | L22: =SUM(L4:L21) -> 1 | M22: =SUM(M4:M21) -> 1 | N22: =SUM(N4:N21) -> 0 | O22: =SUM(O4:O21) -> 0 | ... S22: =SUM(S4:S21) -> 1
A23: 공공 급식 센터 | B23: 공립해남어린이집
B24: 공립화원어린이집
B25: 동심어린이집
B26: 리틀어린이집
B27: 미래클유치원 | K27: 1 | L27: 1 | M27: 1 | N27: 1
B28: 벧엘특수어린이집
B29: 산이어린이집
B30: 색동어린이집
B31: 서림어린이집
B32: 시등어린이집
B33: 신생어린이집
B34: 아트빌어린이집
B35: 예닮어린이집
B36: 예찬어린이집
B37: 원광유치원
B38: 천진어린이집
B39: 한듬어린이집
... B42: 화산어린이집
...

Sheet 공장동03.20
A1: 3/20(금) 해남군공공급식 (3/23~3/27 발주량) | C1: 유기농 백미 천지향 ( ) | E1: 유기농 찹쌀 ( ) | H1: 급식센터 입고 | I1: 유기농 찹쌀현미 ( ) | J1: 유기농 현미 ( ) | K1: 유기농 귀리 (박태일) | L1: 유기농 보리 (김종원) | M1: 유기농 기장 (박태일) | N1: 유기농 흑미 (오점기) | O1: 유기농 차조 (임정옥) | P1: 유기농 팥 (신승철) | Q1: 유기농 발아현미 (곽해용) | R1: 유기농 쥐눈이콩 (신승철) | S1: 유기농 수수 (윤영식) | T1: 유기농 서리태 (신승철)
C2: 10kg | D2: 1kg | E2: 10kg | F2: 1kg | I2: 1kg | J2: 1kg | K2: 1kg | L2: 1kg | M2: 1kg | N2: 1kg | O2: 1kg | P2: 1kg | Q2: 1kg | R2: 1kg | S2: 1kg | T2: 1kg
A3: 품목별 소계 | C3: =SUM(C4:C20) -> 44 | D3: =SUM(D4:D20) -> 0 | E3: =SUM(E4:E20) -> 20 | F3: =SUM(F4:F20) -> 20 | H3: 품목별 소계 | I3: =SUM(I4:I15) -> 5 | J3: =SUM(J4:J15) -> 1 | K3: =SUM(K4:K15) -> 6 | L3: =SUM(L4:L15) -> 7 | M3: =SUM(M4:M15) -> 4 | N3: =SUM(N4:N15) -> 2 | O3: =SUM(O4:O15) -> 5 | P3: =SUM(P4:P15) -> 0 | ... T3: =SUM(T4:T15) -> 1
A4: 싱싱유통 | C4: ='학교별03.20'!C22 -> 0 | D4: ='학교별03.20'!D22 -> 0 | E4: ='학교별03.20'!E22 -> 0 | F4: ='학교별03.20'!F22 -> 0 | H4: 싱싱유통 | I4: ='학교별03.20'!H22 -> 0 | J4: ='학교별03.20'!I22 -> 0 | K4: ='학교별03.20'!J22 -> 1 | L4: ='학교별03.20'!K22 -> 3 | M4: ='학교별03.20'!L22 -> 1 | N4: ='학교별03.20'!M22 -> 1 | O4: ='학교별03.20'!N22 -> 0 | P4: ='학교별03.20'!O22 -> 0 | ... T4: ='학교별03.20'!S22 -> 1
A7: 공공급식센터 | C7: ='학교별03.20'!C43 -> 0 | D7: ='학교별03.20'!D43 -> 0 | E7: ='학교별03.20'!E43 -> 0 | F7: ='학교별03.20'!F43 -> 0 | H7: 급식센터 | I7: ='학교별03.20'!H43 -> 0 | J7: ='학교별03.20'!I43 -> 0 | K7: ='학교별03.20'!J43 -> 0 | L7: ='학교별03.20'!K43 -> 1 | M7: ='학교별03.20'!L43 -> 1 | N7: ='학교별03.20'!M43 -> 1 | O7: ='학교별03.20'!N43 -> 1 | P7: ='학교별03.20'!O43 -> 0 | ... T7: ='학교별03.20'!S43 -> 0
A10: 땅끝농협 | C10: ='학교별03.20'!C52 -> 24 | D10: ='학교별03.20'!D52 -> 0 | E10: ='학교별03.20'!E52 -> 5 | F10: ='학교별03.20'!F52 -> 4 | H10: 땅끝농협 | I10: ='학교별03.20'!H52 -> 5 | J10: ='학교별03.20'!I52 -> 1 | K10: ='학교별03.20'!J52 -> 0 | L10: ='학교별03.20'!K52 -> 0 | M10: ='학교별03.20'!L52 -> 2 | N10: ='학교별03.20'!M52 -> 0 | O10: ='학교별03.20'!N52 -> 1 | P10: ='학교별03.20'!O52 -> 0 | ... T10: ='학교별03.20'!S52 -> 0
A11: 송지고 보관 요청 | C11: -10
A14: 참솔 | C14: ='학교별03.20'!C62 -> 30 | D14: ='학교별03.20'!D62 -> 0 | E14: ='학교별03.20'!E62 -> 15 | F14: ='학교별03.20'!F62 -> 16 | H14: 참솔 | I14: ='학교별03.20'!H62 -> 1 | J14: ='학교별03.20'!I62 -> 0 | K14: ='학교별03.20'!J62 -> 5 | L14: ='학교별03.20'!K62 -> 3 | M14: ='학교별03.20'!L62 -> 0 | N14: ='학교별03.20'!M62 -> 0 | O14: ='학교별03.20'!N62 -> 3 | P14: ='학교별03.20'!O62 -> 0 | ... T14: ='학교별03.20'!S62 -> 0
A15: 화산초 찰현미 선입고 완료 | I15: -1

Sheet 학교별03.27
A1: 3/27(금) 해남군공공급식 (3/30~4/3 발주량) | C1: 유기농 백미 ( ) | E1: 유기농 찹쌀 ( ) | H1: 유기농 찹쌀현미 ( ) | I1: 유기농 현미 ( ) | J1: 유기농 귀리 ( ) | K1: 유기농 보리 ( ) | L1: 유기농 기장 ( ) | M1: 유기농 흑미 ( ) | N1: 유기농 차조 ( ) | O1: 유기농 팥 ( ) | P1: 유기농 발아현미 ( ) | Q1: 유기농 쥐눈이콩 ( ) | R1: 유기농 수수 ( ) | S1: 유기농 서리태 ( )
C2: 10kg | D2: 1kg | E2: 10kg | F2: 1kg | H2: 1kg | I2: 1kg | J2: 1kg | K2: 1kg | L2: 1kg | M2: 1kg | N2: 1kg | O2: 1kg | P2: 1kg | Q2: 1kg | R2: 1kg | S2: 1kg
A3: 업체 | B3: 품목별 소계 | C3: =C22+C43+C52+C62 -> 120 | D3: =D22+D43+D52+D62 -> 0 | E3: =E22+E43+E52+E62 -> 21 | F3: =F22+F43+F52+F62 -> 90 | H3: =H22+H43+H52+H62 -> 9 | I3: =I22+I43+I52+I62 -> 5 | J3: =J22+J43+J52+J62 -> 4 | K3: =K22+K43+K52+K62 -> 12 | L3: =L22+L43+L52+L62 -> 7 | M3: =M22+M43+M52+M62 -> 2 | N3: =N22+N43+N52+N62 -> 10 | O3: =O22+O43+O52+O62 -> 0 | ... S3: =S22+S43+S52+S62 -> 0 | T3: =D3*10 -> 0 | U3: =F3*10+E3 -> 921 | V3: =SUM(H3:Q3) -> 51 | W3: =SUM(T3:V3) -> 972
A4: 싱싱 유통 | B4: 두륜중학교
B5: 마산초등학교 | F5: 1 | J5: 1 | K5: 1
B6: 북일초등학교 | L6: 1 | R6: 1
B7: 북평중학교 | L7: 1
B8: 북평초등학교 | K8: 1
B9: 산이서초등학교 | C9: 4 | K9: 1
B10: 산이중학교
B11: 산이초등학교 | C11: 3 | F11: 6
B12: 우수영중학교 | C12: 8 | F12: 25
B13: 우수영초등학교 | H13: 1 | L13: 1
B14: 해남고등학교
B15: 현산중학교 | C15: 6 | H15: 1 | J15: 1
B16: 현산초등학교 | F16: 20 | R16: 1
B17: 화원고등학교
B18: 화원중학교
B19: 화원초등학교 | C19: 1 | F19: 3 | K19: 1 | N19: 1
B20: 황산중학교 | C20: 5
B21: 황산초등학교 | C21: 4 | F21: 3 | N21: 1
C22: =SUM(C4:C21) -> 31 | D22: =SUM(D4:D21) -> 0 | E22: =SUM(E4:E21) -> 0 | F22: =SUM(F4:F21) -> 58 | H22: =SUM(H4:H21) -> 2 | I22: =SUM(I4:I21) -> 0 | J22: =SUM(J4:J21) -> 2 | K22: =SUM(K4:K21) -> 4 | L22: =SUM(L4:L21) -> 3 | M22: =SUM(M4:M21) -> 0 | N22: =SUM(N4:N21) -> 2 | O22: =SUM(O4:O21) -> 0 | ... S22: =SUM(S4:S21) -> 0
A23: 공공 급식 센터 | B23: 공립시등어린이집 | C23: 2
B24: 공립한듬어린이집 | C24: 3 | F24: 20
B25: 공립화원어린이집
B26: 공립해남어린이집
B27: 공립해담어린이집 | C27: 2 | E27: 1
B28: 동심어린이집
B29: 리틀어린이집
B30: 미래클유치원 | C30: 7 | E30: 2 | L30: 1
B31: 벧엘특수어린이집
B32: 산이어린이집 | C32: 1
B33: 색동어린이집
B34: 서림어린이집
B35: 신생어린이집
B36: 아트빌어린이집 | C36: 20 | E36: 10 | I36: 5
B37: 예닮어린이집 | L37: 1
B38: 예찬어린이집 | C38: 5
B39: 원광유치원
B40: 천진어린이집
...

Sheet 공장동03.27
A1: 3/27(금) 해남군공공급식 (3/30~4/3 발주량) | C1: 유기농 백미 천지향 ( ) | E1: 유기농 찹쌀 ( ) | H1: 급식센터 입고 | I1: 유기농 찹쌀현미 ( ) | J1: 유기농 현미 ( ) | K1: 유기농 귀리 (박태일) | L1: 유기농 보리 (김종원) | M1: 유기농 기장 (박태일) | N1: 유기농 흑미 (오점기) | O1: 유기농 차조 (임정옥) | P1: 유기농 팥 (신승철) | Q1: 유기농 발아현미 (박오주) | R1: 유기농 쥐눈이콩 (신승철) | S1: 유기농 수수 (윤영식) | T1: 유기농 서리태 ( )
C2: 10kg | D2: 1kg | E2: 10kg | F2: 1kg | I2: 1kg | J2: 1kg | K2: 1kg | L2: 1kg | M2: 1kg | N2: 1kg | O2: 1kg | P2: 1kg | Q2: 1kg | R2: 1kg | S2: 1kg | T2: 1kg
A3: 품목별 소계 | C3: =SUM(C4:C19) -> 115 | D3: =SUM(D4:D19) -> 0 | E3: =SUM(E4:E19) -> 21 | F3: =SUM(F4:F19) -> 90 | H3: 품목별 소계 | I3: =SUM(I4:I14) -> 9 | J3: =SUM(J4:J14) -> 5 | K3: =SUM(K4:K14) -> 4 | L3: =SUM(L4:L14) -> 12 | M3: =SUM(M4:M14) -> 7 | N3: =SUM(N4:N14) -> 2 | O3: =SUM(O4:O14) -> 10 | P3: =SUM(P4:P14) -> 0 | ... T3: =SUM(T4:T14) -> 0
A4: 싱싱유통 | C4: ='학교별03.27'!C22 -> 31 | D4: ='학교별03.27'!D22 -> 0 | E4: ='학교별03.27'!E22 -> 0 | F4: ='학교별03.27'!F22 -> 58 | H4: 싱싱유통 | I4: ='학교별03.27'!H22 -> 2 | J4: ='학교별03.27'!I22 -> 0 | K4: ='학교별03.27'!J22 -> 2 | L4: ='학교별03.27'!K22 -> 4 | M4: ='학교별03.27'!L22 -> 3 | N4: ='학교별03.27'!M22 -> 0 | O4: ='학교별03.27'!N22 -> 2 | P4: ='학교별03.27'!O22 -> 0 | ... T4: ='학교별03.27'!S22 -> 0
A7: 공공급식센터 | C7: ='학교별03.27'!C43 -> 40 | D7: ='학교별03.27'!D43 -> 0 | E7: ='학교별03.27'!E43 -> 13 | F7: ='학교별03.27'!F43 -> 20 | H7: 급식센터 | I7: ='학교별03.27'!H43 -> 0 | J7: ='학교별03.27'!I43 -> 5 | K7: ='학교별03.27'!J43 -> 0 | L7: ='학교별03.27'!K43 -> 0 | M7: ='학교별03.27'!L43 -> 2 | N7: ='학교별03.27'!M43 -> 0 | O7: ='학교별03.27'!N43 -> 0 | P7: ='학교별03.27'!O43 -> 0 | ... T7: ='학교별03.27'!S43 -> 0
A10: 땅끝농협 | C10: ='학교별03.27'!C52 -> 38 | D10: ='학교별03.27'!D52 -> 0 | E10: ='학교별03.27'!E52 -> 8 | F10: ='학교별03.27'!F52 -> 5 | H10: 땅끝농협 | I10: ='학교별03.27'!H52 -> 7 | J10: ='학교별03.27'!I52 -> 0 | K10: ='학교별03.27'!J52 -> 2 | L10: ='학교별03.27'!K52 -> 7 | M10: ='학교별03.27'!L52 -> 0 | N10: ='학교별03.27'!M52 -> 2 | O10: ='학교별03.27'!N52 -> 0 | P10: ='학교별03.27'!O52 -> 0 | ... T10: ='학교별03.27'!S52 -> 0
A13: 참솔 | C13: ='학교별03.27'!C62 -> 11 | D13: ='학교별03.27'!D62 -> 0 | E13: ='학교별03.27'!E62 -> 0 | F13: ='학교별03.27'!F62 -> 7 | H13: 참솔 | I13: ='학교별03.27'!H62 -> 0 | J13: ='학교별03.27'!I62 -> 0 | K13: ='학교별03.27'!J62 -> 0 | L13: ='학교별03.27'!K62 -> 1 | M13: ='학교별03.27'!L62 -> 2 | N13: ='학교별03.27'!M62 -> 0 | O13: ='학교별03.27'!N62 -> 8 | P13: ='학교별03.27'!O62 -> 0 | ... T13: ='학교별03.27'!S62 -> 0
A14: 해오름 선입고 완료 | C14: -5

Sheet 학교별04.03
A1: 4/3(금) 해남군공공급식 (4/6~4/10 발주량) | C1: 유기농 백미 ( ) | E1: 유기농 찹쌀 ( ) | H1: 유기농 찹쌀현미 ( ) | I1: 유기농 현미 ( ) | J1: 유기농 귀리 ( ) | K1: 유기농 보리 ( ) | L1: 유기농 기장 ( ) | M1: 유기농 흑미 ( ) | N1: 유기농 차조 ( ) | O1: 유기농 팥 ( ) | P1: 유기농 발아현미 ( ) | Q1: 유기농 쥐눈이콩 ( ) | R1: 유기농 수수 ( ) | S1: 유기농 서리태 ( )
C2: 10kg | D2: 1kg | E2: 10kg | F2: 1kg | H2: 1kg | I2: 1kg | J2: 1kg | K2: 1kg | L2: 1kg | M2: 1kg | N2: 1kg | O2: 1kg | P2: 1kg | Q2: 1kg | R2: 1kg | S2: 1kg
A3: 업체 | B3: 품목별 소계 | C3: =C22+C43+C52+C62 -> 104 | D3: =D22+D43+D52+D62 -> 0 | E3: =E22+E43+E52+E62 -> 9 | F3: =F22+F43+F52+F62 -> 50 | H3: =H22+H43+H52+H62 -> 0 | I3: =I22+I43+I52+I62 -> 0 | J3: =J22+J43+J52+J62 -> 1 | K3: =K22+K43+K52+K62 -> 3 | L3: =L22+L43+L52+L62 -> 10 | M3: =M22+M43+M52+M62 -> 3 | N3: =N22+N43+N52+N62 -> 6 | O3: =O22+O43+O52+O62 -> 0 | ... S3: =S22+S43+S52+S62 -> 0 | T3: =D3*10 -> 0 | U3: =F3*10+E3 -> 509 | V3: =SUM(H3:Q3) -> 26 | W3: =SUM(T3:V3) -> 535
A4: 싱싱 유통 | B4: 두륜중학교
B5: 마산초등학교 | C5: 2 | F5: 4 | N5: 1 | P5: 1
B6: 북일초등학교 | C6: 3 | F6: 8 | N6: 1
B7: 북평중학교 | C7: 5 | M7: 1
B8: 북평초등학교
B9: 산이서초등학교 | F9: 2 | J9: 1
B10: 산이중학교 | C10: 9 | F10: 10 | M10: 1
B11: 산이초등학교 | C11: 3 | F11: 5
B12: 우수영중학교
B13: 우수영초등학교 | C13: 2 | F13: 8 | L13: 1 | R13: 1
B14: 해남고등학교 | C14: 50 | E14: 5
B15: 현산중학교
B16: 현산초등학교 | C16: 8
B17: 화원고등학교
B18: 화원중학교 | C18: 11
B19: 화원초등학교 | C19: 2 | F19: 5 | L19: 1 | R19: 1
B20: 황산중학교 | F20: 3
B21: 황산초등학교 | F21: 5
C22: =SUM(C4:C21) -> 95 | D22: =SUM(D4:D21) -> 0 | E22: =SUM(E4:E21) -> 5 | F22: =SUM(F4:F21) -> 50 | H22: =SUM(H4:H21) -> 0 | I22: =SUM(I4:I21) -> 0 | J22: =SUM(J4:J21) -> 1 | K22: =SUM(K4:K21) -> 0 | L22: =SUM(L4:L21) -> 2 | M22: =SUM(M4:M21) -> 2 | N22: =SUM(N4:N21) -> 2 | O22: =SUM(O4:O21) -> 0 | ... S22: =SUM(S4:S21) -> 0
A23: 공공 급식 센터 | B23: 공립시등어린이집
B24: 공립한듬어린이집
B25: 공립화원어린이집
B26: 공립해남어린이집 | C26: 2 | E26: 1 | N26: 1
B27: 공립해담어린이집
B28: 동심어린이집
B29: 리틀어린이집
B30: 미래클유치원 | N30: 1
B31: 벧엘특수어린이집 | C31: 2 | E31: 1
B32: 산이어린이집
B33: 색동어린이집 | C33: 2
B34: 서림어린이집
B35: 신생어린이집
B36: 아트빌어린이집
B37: 예닮어린이집 | E37: 1
B38: 예찬어린이집
B39: 원광유치원
B40: 천진어린이집
...

Sheet 공장동04.03
A1: 4/3(금) 해남군공공급식 (4/6~4/10 발주량) | C1: 유기농 백미 천지향 ( ) | E1: 유기농 찹쌀 ( ) | H1: 급식센터 입고 | I1: 유기농 찹쌀현미 ( ) | J1: 유기농 현미 ( ) | K1: 유기농 귀리 (박태일) | L1: 유기농 보리 (김종원) | M1: 유기농 기장 (박태일) | N1: 유기농 흑미 (오점기) | O1: 유기농 차조 (임정옥) | P1: 유기농 팥 (신승철) | Q1: 유기농 발아현미 (박오주) | R1: 유기농 쥐눈이콩 (신승철) | S1: 유기농 수수 (윤영식) | T1: 유기농 서리태 ( )
C2: 10kg | D2: 1kg | E2: 10kg | F2: 1kg | I2: 1kg | J2: 1kg | K2: 1kg | L2: 1kg | M2: 1kg | N2: 1kg | O2: 1kg | P2: 1kg | Q2: 1kg | R2: 1kg | S2: 1kg | T2: 1kg
A3: 품목별 소계 | C3: =SUM(C4:C19) -> 54 | D3: =SUM(D4:D19) -> 0 | E3: =SUM(E4:E19) -> 9 | F3: =SUM(F4:F19) -> 50 | H3: 품목별 소계 | I3: =SUM(I4:I14) -> 0 | J3: =SUM(J4:J14) -> 0 | K3: =SUM(K4:K14) -> 1 | L3: =SUM(L4:L14) -> 3 | M3: =SUM(M4:M14) -> 10 | N3: =SUM(N4:N14) -> 3 | O3: =SUM(O4:O14) -> 6 | P3: =SUM(P4:P14) -> 0 | ... T3: =SUM(T4:T14) -> 0
A4: 싱싱유통 | C4: ='학교별04.03'!C22 -> 95 | D4: ='학교별04.03'!D22 -> 0 | E4: ='학교별04.03'!E22 -> 5 | F4: ='학교별04.03'!F22 -> 50 | H4: 싱싱유통 | I4: ='학교별04.03'!H22 -> 0 | J4: ='학교별04.03'!I22 -> 0 | K4: ='학교별04.03'!J22 -> 1 | L4: ='학교별04.03'!K22 -> 0 | M4: ='학교별04.03'!L22 -> 2 | N4: ='학교별04.03'!M22 -> 2 | O4: ='학교별04.03'!N22 -> 2 | P4: ='학교별04.03'!O22 -> 0 | ... T4: ='학교별04.03'!S22 -> 0
A5: 해남고등학교 보관 요청 | C5: -50
A7: 공공급식센터 | C7: ='학교별04.03'!C43 -> 9 | D7: ='학교별04.03'!D43 -> 0 | E7: ='학교별04.03'!E43 -> 4 | F7: ='학교별04.03'!F43 -> 0 | H7: 급식센터 | I7: ='학교별04.03'!H43 -> 0 | J7: ='학교별04.03'!I43 -> 0 | K7: ='학교별04.03'!J43 -> 0 | L7: ='학교별04.03'!K43 -> 0 | M7: ='학교별04.03'!L43 -> 0 | N7: ='학교별04.03'!M43 -> 0 | O7: ='학교별04.03'!N43 -> 2 | P7: ='학교별04.03'!O43 -> 0 | ... T7: ='학교별04.03'!S43 -> 0
A10: 땅끝농협 | C10: ='학교별04.03'!C52 -> 0 | D10: ='학교별04.03'!D52 -> 0 | E10: ='학교별04.03'!E52 -> 0 | F10: ='학교별04.03'!F52 -> 0 | H10: 땅끝농협 | I10: ='학교별04.03'!H52 -> 0 | J10: ='학교별04.03'!I52 -> 0 | K10: ='학교별04.03'!J52 -> 0 | L10: ='학교별04.03'!K52 -> 1 | M10: ='학교별04.03'!L52 -> 3 | N10: ='학교별04.03'!M52 -> 1 | O10: ='학교별04.03'!N52 -> 0 | P10: ='학교별04.03'!O52 -> 0 | ... T10: ='학교별04.03'!S52 -> 0
A13: 참솔 | C13: ='학교별04.03'!C62 -> 0 | D13: ='학교별04.03'!D62 -> 0 | E13: ='학교별04.03'!E62 -> 0 | F13: ='학교별04.03'!F62 -> 0 | H13: 참솔 | I13: ='학교별04.03'!H62 -> 0 | J13: ='학교별04.03'!I62 -> 0 | K13: ='학교별04.03'!J62 -> 0 | L13: ='학교별04.03'!K62 -> 2 | M13: ='학교별04.03'!L62 -> 5 | N13: ='학교별04.03'!M62 -> 0 | O13: ='학교별04.03'!N62 -> 2 | P13: ='학교별04.03'!O62 -> 0 | ... T13: ='학교별04.03'!S62 -> 0

Sheet 학교별04.10
A1: 4/10(금) 해남군공공급식 (4/13~4/17 발주량) | C1: 유기농 백미 ( ) | E1: 유기농 찹쌀 ( ) | H1: 유기농 찹쌀현미 ( ) | I1: 유기농 현미 ( ) | J1: 유기농 귀리 ( ) | K1: 유기농 보리 ( ) | L1: 유기농 기장 ( ) | M1: 유기농 흑미 ( ) | N1: 유기농 차조 ( ) | O1: 유기농 팥 ( ) | P1: 유기농 발아현미 ( ) | Q1: 유기농 쥐눈이콩 ( ) | R1: 유기농 수수 ( ) | S1: 유기농 서리태 ( )
C2: 10kg | D2: 1kg | E2: 10kg | F2: 1kg | H2: 1kg | I2: 1kg | J2: 1kg | K2: 1kg | L2: 1kg | M2: 1kg | N2: 1kg | O2: 1kg | P2: 1kg | Q2: 1kg | R2: 1kg | S2: 1kg
A3: 업체 | B3: 품목별 소계 | C3: =C22+C43+C52+C62 -> 89 | D3: =D22+D43+D52+D62 -> 0 | E3: =E22+E43+E52+E62 -> 12 | F3: =F22+F43+F52+F62 -> 34 | H3: =H22+H43+H52+H62 -> 3 | I3: =I22+I43+I52+I62 -> 0 | J3: =J22+J43+J52+J62 -> 3 | K3: =K22+K43+K52+K62 -> 8 | L3: =L22+L43+L52+L62 -> 12 | M3: =M22+M43+M52+M62 -> 3 | N3: =N22+N43+N52+N62 -> 0 | O3: =O22+O43+O52+O62 -> 1 | ... S3: =S22+S43+S52+S62 -> 0 | T3: =D3*10 -> 0 | U3: =F3*10+E3 -> 352 | V3: =SUM(H3:Q3) -> 33 | W3: =SUM(T3:V3) -> 385
A4: 싱싱 유통 | B4: 두륜중학교
B5: 마산초등학교 | C5: 2 | F5: 5 | K5: 1 | L5: 1
B6: 북일초등학교 | C6: 3 | F6: 8
B7: 북평중학교
B8: 북평초등학교
B9: 산이서초등학교 | F9: 1 | M9: 1
B10: 산이중학교
B11: 산이초등학교 | O11: 1
B12: 우수영중학교
B13: 우수영초등학교 | C13: 2 | F13: 8
B14: 해남고등학교 | C14: 50 | E14: 5
B15: 현산중학교 | L15: 1
B16: 현산초등학교 | L16: 1
B17: 화원고등학교
B18: 화원중학교 | C18: 11 | E18: 3
B19: 화원초등학교 | F19: 5
B20: 황산중학교 | F20: 2
B21: 황산초등학교 | C21: 3 | F21: 5 | R21: 1
C22: =SUM(C4:C21) -> 71 | D22: =SUM(D4:D21) -> 0 | E22: =SUM(E4:E21) -> 8 | F22: =SUM(F4:F21) -> 34 | H22: =SUM(H4:H21) -> 0 | I22: =SUM(I4:I21) -> 0 | J22: =SUM(J4:J21) -> 0 | K22: =SUM(K4:K21) -> 1 | L22: =SUM(L4:L21) -> 3 | M22: =SUM(M4:M21) -> 1 | N22: =SUM(N4:N21) -> 0 | O22: =SUM(O4:O21) -> 1 | ... S22: =SUM(S4:S21) -> 0
A23: 공공 급식 센터 | B23: 공립시등어린이집 | C23: 2
B24: 공립한듬어린이집
B25: 공립화원어린이집
B26: 공립해남어린이집 | C26: 2 | J26: 1 | L26: 1
B27: 공립해담어린이집 | C27: 2 | E27: 1
B28: 동심어린이집
B29: 리틀어린이집
B30: 미래클유치원 | C30: 8 | E30: 3 | L30: 1
B31: 벧엘특수어린이집 | C31: 1
B32: 산이어린이집 | C32: 1
B33: 색동어린이집 | C33: 2
B34: 서림어린이집
B35: 신생어린이집
B36: 아트빌어린이집
B37: 예닮어린이집
B38: 예찬어린이집
B39: 원광유치원
B40: 천진어린이집
...

Sheet 공장동04.10
A1: 4/10(금) 해남군공공급식 (4/13~4/17 발주량) | C1: 유기농 백미 천지향 ( ) | E1: 유기농 찹쌀 ( ) | H1: 급식센터 입고 | I1: 유기농 찹쌀현미 ( ) | J1: 유기농 현미 ( ) | K1: 유기농 귀리 (박태일) | L1: 유기농 보리 (김종원) | M1: 유기농 기장 (박태일) | N1: 유기농 흑미 (오점기) | O1: 유기농 차조 (임정옥) | P1: 유기농 팥 (신승철) | Q1: 유기농 발아현미 (박오주) | R1: 유기농 쥐눈이콩 (신승철) | S1: 유기농 수수 (윤영식) | T1: 유기농 서리태 ( )
C2: 10kg | D2: 1kg | E2: 10kg | F2: 1kg | I2: 1kg | J2: 1kg | K2: 1kg | L2: 1kg | M2: 1kg | N2: 1kg | O2: 1kg | P2: 1kg | Q2: 1kg | R2: 1kg | S2: 1kg | T2: 1kg
A3: 품목별 소계 | C3: =SUM(C4:C19) -> 89 | D3: =SUM(D4:D19) -> 0 | E3: =SUM(E4:E19) -> 12 | F3: =SUM(F4:F19) -> 34 | H3: 품목별 소계 | I3: =SUM(I4:I14) -> 3 | J3: =SUM(J4:J14) -> 0 | K3: =SUM(K4:K14) -> 3 | L3: =SUM(L4:L14) -> 8 | M3: =SUM(M4:M14) -> 12 | N3: =SUM(N4:N14) -> 3 | O3: =SUM(O4:O14) -> 0 | P3: =SUM(P4:P14) -> 1 | ... T3: =SUM(T4:T14) -> 0
